Workbook

Sheet Construction Plan
A1: 439 Manning Ave: Construction Plan
A2: Kyle Luong & Nancy Song | Third-floor rear addition + bedroom reconfiguration | PalmView Contracting Inc. | Prepared for Raff Di Palma
A4: PROJECT SUMMARY
A5: Address | B5: 439 Manning Ave, Toronto, ON M6G 2V6
A6: JobTread job | B6: #5 Manning Ave: Home Addition
A7: Scope | B7: New ~245 sq ft third-floor rear lounge over the existing 2nd-storey flat roof, sitting room converted to a bedroom, hall. 405.66 sq ft finished. No foundation work, no plumbing.
A8: Contract signed | B8: New Addition Proposal, issued Apr 3, 2026 (JobTread doc #1)
A9: Excluded from base | B9: Windows and exterior doors (supply + install), and all finish materials: hardwood, interior doors, hardware. Client-paid.
A10: Project manager | B10: David Magarici
A11: Architect / design | B11: Pino (La Vecchia Designs)
A13: STATUS (as of Oct 20, 2026)
A14: Item | B14: Detail | E14: Status
A15: Committee of Adjustment | B15: Approved Sep 23, 2026 (client notified Sep 25). Neighbour support letters on file. | E15: Done
A16: Zoning review (permit drawings) | B16: Submitted. Response expected about Oct 27. | E16: In progress
A17: Building permit | B17: Not yet applied for. Apply as soon as zoning clears. | E17: Not started
A18: Tendering | B18: Bids in for most divisions; Fabiano, Doctor Demo and New Age still pending. Deadline Thu Oct 22, 7 PM (David). | E18: In progress
A19: Construction schedule | B19: Draft below. David to finalize with trades by Thu Oct 22, 7 PM. | E19: In progress
A20: Start date communicated to client | B20: Aug 17: end of Oct / early Nov (tentative). Kyle asked again Oct 13; no firm date sent yet. | E20: Action needed
A22: FINANCIAL SNAPSHOT (live from the Finances tabs)
A23: Contract total (pre-HST) | B23: ='Payment Schedule'!$B$4 -> 123030.16
A24: Base scope sell: 2.0 Rear Addition | B24: =Inputs!$B$5 -> 114070
A25: Cost target at 35% markup | B25: =Leveling!$E$19 -> 84496.296
A26: Base cost: current bids (Renomar) | B26: =Leveling!$E$20 -> 122296.69
A27: Base cost: Fabiano scenario | B27: =Leveling!$F$20 -> 85196.69
A28: Margin: current bids | B28: =Leveling!$E$23 -> -0.072119663
A29: Margin: Fabiano scenario | B29: =Leveling!$F$23 -> 0.25311923
A30: All-in margin, Fabiano (incl. contingency + provisional) | B30: =Leveling!$F$32 -> 0.13459841
A31: Collected to date (incl. HST) | B31: ='Payment Schedule'!$G$17 -> 6951.204
A32: Still to invoice (incl. HST) | B32: ='Payment Schedule'!$H$17 -> 132072.88
A34: KEY RISKS AND DECISIONS
A35: 1. | B35: Fabiano's General Works price decides the margin. Confirm it includes demo, licensed electrical + ESA, and drywall/insulation/trim materials.
A36: 2. | B36: Brick veneer add-on: lowest bid $31,200 vs about $8,000 told to the client. Re-quote before Kyle, Nancy or neighbour Peter commit.
A37: 3. | B37: Interior brick wall add-on: $10,800 bid vs about $3,600 quoted to the client.
A38: 4. | B38: Structural engineering not yet issued. Reinforcement below is a change order per contract ($5,000 provisional carried).
A39: 5. | B39: Winter build: the roof is open from demo until the flat roof is on (about 4.5 weeks in Jan to Feb). Budget temporary heat and weather protection, or hold demo until the permit date is firm.
A40: 6. | B40: Bedroom egress window and side-wall limiting distance to be confirmed with the designer before windows are ordered.
A41: 7. | B41: Window lead time drives the schedule. Client must order as soon as sizes are locked off framing.

Sheet Schedule
A1: 439 Manning Ave: Construction Schedule (draft)
A2: Durations are planning estimates. David to confirm each one with the trade by Thu Oct 22. Change the yellow cells; dates update.
A4: Expected permit issue date | B4: 46360 | C4: Estimate: zoning response ~Oct 27, then permit application; City review assumed ~5 weeks. Replace with the real date.
A5: Mobilization lead after permit (days) | B5: 7 | C5: Time to book trades, bin, scaffold and protection after permit.
A6: Construction start | B6: =B4+B5 -> 46367
A7: Substantial completion | B7: =F24 -> 46516
A8: Total duration (weeks) | B8: =SUM(D11:D24) -> 21
A10: # | B10: Phase / task | C10: Trade | D10: Duration (weeks) | E10: Start | F10: Finish | G10: Inspection / milestone | H10: Payment milestone
A11: 1 | B11: Mobilize: protection, bin, scaffold, portable toilet | C11: PalmView / Site services | D11: 1 | E11: =$B$6 -> 46367 | F11: =E11+ROUND(D11*7,0) -> 46374 | H11: Construction Start (15%)
A12: 2 | B12: Holiday shutdown: roof stays closed until the new year | C12: None | D12: 2.5 | E12: =F11 -> 46374 | F12: =E12+ROUND(D12*7,0) -> 46392
A13: 3 | B13: Demolition: rear roof removal + temporary weather protection | C13: Fabiano / demo contractor | D13: 1 | E13: =F12 -> 46392 | F13: =E13+ROUND(D13*7,0) -> 46399
A14: 4 | B14: Framing: floor system, walls, flat roof, beams, ridge raise | C14: Aryan (framing) + lumber | D14: 3 | E14: =F13 -> 46399 | F14: =E14+ROUND(D14*7,0) -> 46420 | G14: Framing inspection | H14: Framing Complete (30%)
A15: 5 | B15: Flat roofing, parapet flashing, skylight | C15: Safety Roofing | D15: 1.5 | E15: =F14 -> 46420 | F15: =E15+ROUND(D15*7,0) -> 46431
A16: 6 | B16: Window install (client-supplied units) | C16: Window supplier | D16: 1 | E16: =F15 -> 46431 | F16: =E16+ROUND(D16*7,0) -> 46438
A17: 7 | B17: Siding / cladding + flashing | C17: Safety Roofing | D17: 2 | E17: =F16 -> 46438 | F17: =E17+ROUND(D17*7,0) -> 46452
A18: 8 | B18: HVAC rough-in + electrical rough-in | C18: Ideal Heating / Fabiano electrician | D18: 1.5 | E18: =F17 -> 46452 | F18: =E18+ROUND(D18*7,0) -> 46463 | G18: ESA rough-in inspection | H18: Electrical Rough-ins Complete (15%)
A19: 9 | B19: Spray foam (roof) + batt insulation + vapour barrier | C19: FoamIt / Fabiano | D19: 1 | E19: =F18 -> 46463 | F19: =E19+ROUND(D19*7,0) -> 46470 | G19: Insulation inspection
A20: 10 | B20: Drywall: board, tape, plaster, sand, prime | C20: Fabiano | D20: 2 | E20: =F19 -> 46470 | F20: =E20+ROUND(D20*7,0) -> 46484 | H20: Drywall Boarding Complete (10%)
A21: 11 | B21: Painting: finish coats | C21: Fabiano | D21: 1 | E21: =F20 -> 46484 | F21: =E21+ROUND(D21*7,0) -> 46491
A22: 12 | B22: Hardwood flooring + trim + interior doors (client-supplied) | C22: Fabiano | D22: 1.5 | E22: =F21 -> 46491 | F22: =E22+ROUND(D22*7,0) -> 46502 | H22: Flooring Installed (10%)
A23: 13 | B23: HVAC + electrical finish, devices, commissioning | C23: Ideal Heating / Fabiano electrician | D23: 1 | E23: =F22 -> 46502 | F23: =E23+ROUND(D23*7,0) -> 46509 | G23: ESA final
A24: 14 | B24: Punch list, clean-up, strip protection | C24: Fabiano / PalmView | D24: 1 | E24: =F23 -> 46509 | F24: =E24+ROUND(D24*7,0) -> 46516 | G24: Final building inspection | H24: Punch List (5%)
A26: Tasks run one after another, which is conservative. Overlaps (e.g. siding while roughing in) can shorten it once David confirms crews. Weeks are calendar weeks, Monday to Friday site hours (T&C 16.1).

Sheet Payment Schedule
A1: 439 Manning Ave: Client Payment Schedule
A2: Contract milestones from JobTread invoices #2 to #9. Paid / status per JobTread on Oct 20, 2026.
A4: Contract total (pre-HST) | B4: 123030.16 | C4: JobTread New Addition Proposal (doc #1), approved. Includes design fees.
A5: HST rate | B5: 0.13
A6: Design fees + other (contract total less base scope sell) | B6: =B4-Inputs!$B$5 -> 8960.16
A8: Milestone | B8: % of contract | C8: Amount (pre-HST) | D8: HST | E8: Total incl. HST | F8: Status | G8: Collected (incl. HST) | H8: To invoice (incl. HST) | I8: Expected date
A9: Deposit | B9: 0.05 | C9: =$B$4*B9 -> 6151.508 | D9: =C9*$B$5 -> 799.69604 | E9: =C9+D9 -> 6951.204 | F9: Paid | G9: =IF(F9="Paid",E9,0) -> 6951.204 | H9: =E9-G9 -> 0 | I9: Jul 10, 2026 (invoiced)
A10: Building Permit Submission | B10: 0.1 | C10: =$B$4*B10 -> 12303.016 | D10: =C10*$B$5 -> 1599.3921 | E10: =C10+D10 -> 13902.408 | F10: Draft | G10: =IF(F10="Paid",E10,0) -> 0 | H10: =E10-G10 -> 13902.408 | I10: When permit is applied for
A11: Construction Start Date | B11: 0.15 | C11: =$B$4*B11 -> 18454.524 | D11: =C11*$B$5 -> 2399.0881 | E11: =C11+D11 -> 20853.612 | F11: Draft | G11: =IF(F11="Paid",E11,0) -> 0 | H11: =E11-G11 -> 20853.612 | I11: =Schedule!$E$11 -> 46367
A12: Framing Complete | B12: 0.3 | C12: =$B$4*B12 -> 36909.048 | D12: =C12*$B$5 -> 4798.1762 | E12: =C12+D12 -> 41707.224 | F12: Draft | G12: =IF(F12="Paid",E12,0) -> 0 | H12: =E12-G12 -> 41707.224 | I12: =Schedule!$F$14 -> 46420
A13: Electrical Rough-ins Complete | B13: 0.15 | C13: =$B$4*B13 -> 18454.524 | D13: =C13*$B$5 -> 2399.0881 | E13: =C13+D13 -> 20853.612 | F13: Draft | G13: =IF(F13="Paid",E13,0) -> 0 | H13: =E13-G13 -> 20853.612 | I13: =Schedule!$F$18 -> 46463
A14: Drywall Boarding Complete | B14: 0.1 | C14: =$B$4*B14 -> 12303.016 | D14: =C14*$B$5 -> 1599.3921 | E14: =C14+D14 -> 13902.408 | F14: Draft | G14: =IF(F14="Paid",E14,0) -> 0 | H14: =E14-G14 -> 13902.408 | I14: =Schedule!$F$20 -> 46484
A15: Flooring Installed | B15: 0.1 | C15: =$B$4*B15 -> 12303.016 | D15: =C15*$B$5 -> 1599.3921 | E15: =C15+D15 -> 13902.408 | F15: Draft | G15: =IF(F15="Paid",E15,0) -> 0 | H15: =E15-G15 -> 13902.408 | I15: =Schedule!$F$22 -> 46502
A16: Punch List | B16: 0.05 | C16: =$B$4*B16 -> 6151.508 | D16: =C16*$B$5 -> 799.69604 | E16: =C16+D16 -> 6951.204 | F16: Draft | G16: =IF(F16="Paid",E16,0) -> 0 | H16: =E16-G16 -> 6951.204 | I16: =Schedule!$F$24 -> 46516
A17: TOTAL | B17: =SUM(B9:B16) -> 1 | C17: =SUM(C9:C16) -> 123030.16 | D17: =SUM(D9:D16) -> 15993.921 | E17: =SUM(E9:E16) -> 139024.08 | G17: =SUM(G9:G16) -> 6951.204 | H17: =SUM(H9:H16) -> 132072.88
A18: =IF(ROUND(B17,4)=1,"Milestones add to 100%","CHECK: milestones do not add to 100%") -> Milestones add to 100%
A19: Status values: Paid or Draft. Invoices are due within 2 calendar days of issue (T&C 9.1).

Sheet Leveling
A1: 439 Manning Ave: Base Scope Bid Leveling vs Budget and 35% Markup Target
A2: ="Scenario: Fabiano at "&TEXT(Inputs!$B$7,"$#,##0")&IF(Inputs!$B$8="Yes"," incl. demo"," + demo "&TEXT(Inputs!$B$9,"$#,##0"))&" | Roof/siding: "&Inputs!$B$10 -> Scenario: Fabiano at $20,000 incl. demo | Roof/siding: Safety
A4: Division | B4: Budget (cost) | C4: Lowest approved bid | D4: Low bidder | E4: Current: Renomar | F4: Scenario: Fabiano | G4: Scenario vs budget | H4: # prices in | I4: # required (SOP)
A5: General Works (bulk) | B5: 30041 | C5: =_xlfn.MINIFS('All Bids'!$D$5:$D$34,'All Bids'!$A$5:$A$34,"General Works + Demo",'All Bids'!$C$5:$C$34,"Approved",'All Bids'!$D$5:$D$34,">0") -> 57100 | D5: =IFERROR(INDEX('All Bids'!$B$5:$B$34,MATCH("General Works + Demo|"&ROUND(C5,2),'All Bids'!$E$5:$E$34,0)),"No price yet") -> Renomar Inc (Olimpiu) | E5: =C5 -> 57100 | F5: =Inputs!$B$7 -> 20000 | G5: =F5-B5 -> -10041 | H5: =COUNTIFS('All Bids'!$A$5:$A$34,"General Works + Demo",'All Bids'!$C$5:$C$34,"Approved",'All Bids'!$D$5:$D$34,">0") -> 1 | I5: 4
A6: Demolition (separate line) | B6: 6290 | C6: =_xlfn.MINIFS('All Bids'!$D$5:$D$34,'All Bids'!$A$5:$A$34,"Demolition",'All Bids'!$C$5:$C$34,"Approved",'All Bids'!$D$5:$D$34,">0") -> 0 | D6: =IFERROR(INDEX('All Bids'!$B$5:$B$34,MATCH("Demolition|"&ROUND(C6,2),'All Bids'!$E$5:$E$34,0)),"No price yet") -> No price yet | E6: 0 | F6: =IF(Inputs!$B$8="Yes",0,Inputs!$B$9) -> 0 | G6: =F6-B6 -> -6290 | H6: =COUNTIFS('All Bids'!$A$5:$A$34,"Demolition",'All Bids'!$C$5:$C$34,"Approved",'All Bids'!$D$5:$D$34,">0") -> 0 | I6: 3
A7: Framing & Structure | B7: 23128 | C7: =_xlfn.MINIFS('All Bids'!$D$5:$D$34,'All Bids'!$A$5:$A$34,"Framing",'All Bids'!$C$5:$C$34,"Approved",'All Bids'!$D$5:$D$34,">0") -> 14000 | D7: =IFERROR(INDEX('All Bids'!$B$5:$B$34,MATCH("Framing|"&ROUND(C7,2),'All Bids'!$E$5:$E$34,0)),"No price yet") -> Aryan | E7: =C7 -> 14000 | F7: =E7 -> 14000 | G7: =F7-B7 -> -9128 | H7: =COUNTIFS('All Bids'!$A$5:$A$34,"Framing",'All Bids'!$C$5:$C$34,"Approved",'All Bids'!$D$5:$D$34,">0") -> 1 | I7: 3
A8: Lumber Supply | B8: 4900 | C8: =_xlfn.MINIFS('All Bids'!$D$5:$D$34,'All Bids'!$A$5:$A$34,"Lumber",'All Bids'!$C$5:$C$34,"Approved",'All Bids'!$D$5:$D$34,">0") -> 6386.19 | D8: =IFERROR(INDEX('All Bids'!$B$5:$B$34,MATCH("Lumber|"&ROUND(C8,2),'All Bids'!$E$5:$E$34,0)),"No price yet") -> RONA (Jonathan) | E8: =C8 -> 6386.19 | F8: =E8 -> 6386.19 | G8: =F8-B8 -> 1486.19 | H8: =COUNTIFS('All Bids'!$A$5:$A$34,"Lumber",'All Bids'!$C$5:$C$34,"Approved",'All Bids'!$D$5:$D$34,">0") -> 3 | I8: 3
A9: Flat Roofing | B9: 8010 | C9: =_xlfn.MINIFS('All Bids'!$D$5:$D$34,'All Bids'!$A$5:$A$34,"Flat Roofing",'All Bids'!$C$5:$C$34,"Approved",'All Bids'!$D$5:$D$34,">0") -> 15700 | D9: =IFERROR(INDEX('All Bids'!$B$5:$B$34,MATCH("Flat Roofing|"&ROUND(C9,2),'All Bids'!$E$5:$E$34,0)),"No price yet") -> Alps Roofing | E9: =IF(Inputs!$B$10="Split",C9,0) -> 0 | F9: =E9 -> 0 | G9: =IF(Inputs!$B$10="Split",F9-B9,0) -> 0 | H9: =COUNTIFS('All Bids'!$A$5:$A$34,"Flat Roofing",'All Bids'!$C$5:$C$34,"Approved",'All Bids'!$D$5:$D$34,">0") -> 1 | I9: 3
A10: Siding / Cladding | B10: 17750 | C10: =_xlfn.MINIFS('All Bids'!$D$5:$D$34,'All Bids'!$A$5:$A$34,"Siding",'All Bids'!$C$5:$C$34,"Approved",'All Bids'!$D$5:$D$34,">0") -> 7900 | D10: =IFERROR(INDEX('All Bids'!$B$5:$B$34,MATCH("Siding|"&ROUND(C10,2),'All Bids'!$E$5:$E$34,0)),"No price yet") -> Baz Aluminum | E10: =IF(Inputs!$B$10="Split",C10,0) -> 0 | F10: =E10 -> 0 | G10: =IF(Inputs!$B$10="Split",F10-B10,0) -> 0 | H10: =COUNTIFS('All Bids'!$A$5:$A$34,"Siding",'All Bids'!$C$5:$C$34,"Approved",'All Bids'!$D$5:$D$34,">0") -> 1 | I10: 3
A11: Roof + Siding Combo (Safety) | B11: 0 | C11: =_xlfn.MINIFS('All Bids'!$D$5:$D$34,'All Bids'!$A$5:$A$34,"Roof + Siding + Skylight Combo",'All Bids'!$C$5:$C$34,"Approved",'All Bids'!$D$5:$D$34,">0") -> 20580 | D11: =IFERROR(INDEX('All Bids'!$B$5:$B$34,MATCH("Roof + Siding + Skylight Combo|"&ROUND(C11,2),'All Bids'!$E$5:$E$34,0)),"No price yet") -> Safety Roofing (Elvis) | E11: =IF(Inputs!$B$10="Split",0,C11) -> 20580 | F11: =E11 -> 20580 | G11: =IF(Inputs!$B$10="Split",0,F11-(B9+B10)) -> -5180 | H11: =COUNTIFS('All Bids'!$A$5:$A$34,"Roof + Siding + Skylight Combo",'All Bids'!$C$5:$C$34,"Approved",'All Bids'!$D$5:$D$34,">0") -> 1 | I11: 1
A12: HVAC: Mini-Split | B12: 6750 | C12: =_xlfn.MINIFS('All Bids'!$D$5:$D$34,'All Bids'!$A$5:$A$34,"HVAC",'All Bids'!$C$5:$C$34,"Approved",'All Bids'!$D$5:$D$34,">0") -> 9370 | D12: =IFERROR(INDEX('All Bids'!$B$5:$B$34,MATCH("HVAC|"&ROUND(C12,2),'All Bids'!$E$5:$E$34,0)),"No price yet") -> Ideal Heating (Leena) | E12: =C12 -> 9370 | F12: =E12 -> 9370 | G12: =F12-B12 -> 2620 | H12: =COUNTIFS('All Bids'!$A$5:$A$34,"HVAC",'All Bids'!$C$5:$C$34,"Approved",'All Bids'!$D$5:$D$34,">0") -> 2 | I12: 3
A13: Spray Foam | B13: 3430 | C13: =_xlfn.MINIFS('All Bids'!$D$5:$D$34,'All Bids'!$A$5:$A$34,"Spray Foam",'All Bids'!$C$5:$C$34,"Approved",'All Bids'!$D$5:$D$34,">0") -> 3360.5 | D13: =IFERROR(INDEX('All Bids'!$B$5:$B$34,MATCH("Spray Foam|"&ROUND(C13,2),'All Bids'!$E$5:$E$34,0)),"No price yet") -> FoamIt (Nadia) | E13: =C13 -> 3360.5 | F13: =E13 -> 3360.5 | G13: =F13-B13 -> -69.5 | H13: =COUNTIFS('All Bids'!$A$5:$A$34,"Spray Foam",'All Bids'!$C$5:$C$34,"Approved",'All Bids'!$D$5:$D$34,">0") -> 1 | I13: 3
A14: Site Services & Hoisting | B14: 11500 | C14: 0 | D14: No price yet: budget carried | E14: =B14 -> 11500 | F14: =E14 -> 11500 | G14: =F14-B14 -> 0 | H14: 0 | I14: 1
A15: BASE COST TOTAL | B15: =SUM(B5:B14) -> 111799 | E15: =SUM(E5:E14) -> 122296.69 | F15: =SUM(F5:F14) -> 85196.69 | G15: =SUM(G5:G14) -> -26602.31
A17: MARGIN CHECK | E17: Current: Renomar | F17: Scenario: Fabiano
A18: Contract sell (pre-HST) | E18: =Inputs!$B$5 -> 114070 | F18: =Inputs!$B$5 -> 114070
A19: Cost target = sell / (1 + markup) | E19: =Inputs!$B$5/(1+Inputs!$B$6) -> 84496.296 | F19: =Inputs!$B$5/(1+Inputs!$B$6) -> 84496.296
A20: Base cost (from total above) | E20: =E15 -> 122296.69 | F20: =F15 -> 85196.69
A21: Over / (under) cost target | E21: =E20-E19 -> 37800.394 | F21: =F20-F19 -> 700.3937
A22: Gross profit | E22: =E18-E20 -> -8226.69 | F22: =F18-F20 -> 28873.31
A23: Margin (profit / sell) | E23: =IF(E18=0,0,E22/E18) -> -0.072119663 | F23: =IF(F18=0,0,F22/F18) -> 0.25311923
A24: Markup (profit / cost) | E24: =IF(E20=0,0,E22/E20) -> -0.067268296 | F24: =IF(F20=0,0,F22/F20) -> 0.33890178
A25: Target margin at that markup | E25: =Inputs!$B$6/(1+Inputs!$B$6) -> 0.25925926 | F25: =Inputs!$B$6/(1+Inputs!$B$6) -> 0.25925926
A27: RISK VIEW: + contingency + provisional
A28: Contingency | E28: =E20*Inputs!$B$11 -> 12229.669 | F28: =F20*Inputs!$B$11 -> 8519.669
A29: Provisional: structural reinforcement | E29: =Inputs!$B$12 -> 5000 | F29: =Inputs!$B$12 -> 5000
A30: All-in cost | E30: =E20+E28+E29 -> 139526.36 | F30: =F20+F28+F29 -> 98716.359
A31: All-in profit | E31: =E18-E30 -> -25456.359 | F31: =F18-F30 -> 15353.641
A32: All-in margin | E32: =IF(E18=0,0,E31/E18) -> -0.22316436 | F32: =IF(F18=0,0,F31/F18) -> 0.13459841
A34: ADD-ONS: bid vs what the client was told
A35: Add-on | B35: Budget (cost) | C35: Lowest bid | D35: Low bidder | E35: Client was told (sell) | F35: Sell at 35% markup | G35: Gap: needed sell - told
A36: Brick Veneer (exterior) | B36: 36400 | C36: =_xlfn.MINIFS('All Bids'!$D$5:$D$34,'All Bids'!$A$5:$A$34,"Add-on: Brick Veneer",'All Bids'!$C$5:$C$34,"Approved",'All Bids'!$D$5:$D$34,">0") -> 31200 | D36: =IFERROR(INDEX('All Bids'!$B$5:$B$34,MATCH("Add-on: Brick Veneer|"&ROUND(C36,2),'All Bids'!$E$5:$E$34,0)),"No price yet") -> Amoroso Construction | E36: 8000 | F36: =C36*(1+Inputs!$B$6) -> 42120 | G36: =F36-E36 -> 34120
A37: Rustic Interior Brick Wall | B37: 3960 | C37: =_xlfn.MINIFS('All Bids'!$D$5:$D$34,'All Bids'!$A$5:$A$34,"Add-on: Interior Brick",'All Bids'!$C$5:$C$34,"Approved",'All Bids'!$D$5:$D$34,">0") -> 10800 | D37: =IFERROR(INDEX('All Bids'!$B$5:$B$34,MATCH("Add-on: Interior Brick|"&ROUND(C37,2),'All Bids'!$E$5:$E$34,0)),"No price yet") -> Amoroso Construction | E37: 3600 | F37: =C37*(1+Inputs!$B$6) -> 14580 | G37: =F37-E37 -> 10980
A38: Angled Skylight | B38: 4600 | C38: =_xlfn.MINIFS('All Bids'!$D$5:$D$34,'All Bids'!$A$5:$A$34,"Add-on: Skylight",'All Bids'!$C$5:$C$34,"Approved",'All Bids'!$D$5:$D$34,">0") -> 3300 | D38: =IFERROR(INDEX('All Bids'!$B$5:$B$34,MATCH("Add-on: Skylight|"&ROUND(C38,2),'All Bids'!$E$5:$E$34,0)),"No price yet") -> Skylight Services Ltd | E38: 2500 | F38: =C38*(1+Inputs!$B$6) -> 4455 | G38: =F38-E38 -> 1955
A40: Windows: CLIENT-PAID, NOT IN BASE COST (info only) | B40: 8470 | C40: =_xlfn.MINIFS('All Bids'!$D$5:$D$34,'All Bids'!$A$5:$A$34,"Windows (client-paid)",'All Bids'!$C$5:$C$34,"Approved",'All Bids'!$D$5:$D$34,">0") -> 7850 | D40: =IFERROR(INDEX('All Bids'!$B$5:$B$34,MATCH("Windows (client-paid)|"&ROUND(C40,2),'All Bids'!$E$5:$E$34,0)),"No price yet") -> JS Windows and Doors
A41: Finish materials: CLIENT-PAID, NOT IN BASE COST (hardwood, interior doors, hardware) | B41: 7549 | D41: Tender Package P9 budget; client selections
A43: Notes
A44: Amounts come from the cost field on each JobTread bid request. Quote PDFs not reviewed, so scope inclusions and HST treatment are unconfirmed.
A45: Contract sell $114,070 is the 2.0 Rear Addition base only (excludes design fees and add-ons), per the Tender Package margin check.
A46: Base cost EXCLUDES windows (supply + install) and all client finish materials (hardwood, interior doors, hardware). Base includes only the install labour for hardwood, doors and trim inside General Works.
...

Sheet Inputs
A1: 439 Manning Ave: Bid Leveling Inputs
A2: Yellow cells are the levers. Change them and every tab updates. Blue = typed-in number, black = formula, green = pulled from another tab.
A4: Input | B4: Value | C4: Source / note
A5: Contract sell: 2.0 Rear Addition (pre-HST) | B5: 114070 | C5: Tender Package, Margin Check (from invoice #22288). Excludes design fees and add-ons.
A6: Target markup on cost (SOP Step 5) | B6: 0.35 | C6: Tendering SOP: cost target = contract sell / 1.35.
A7: Fabiano General Works price (estimate) | B7: 20000 | C7: Raff's estimate, Oct 20. Replace with the real number when it comes in.
A8: Does Fabiano's price include demolition? (Yes/No) | B8: Yes | C8: The work order asks for demo as a separate line. If No, the demo cost below gets added.
A9: Demolition cost if separate | B9: 6290 | C9: Internal demo budget (P7D). Replace with Fabiano's or Doctor Demo's price.
A10: Roof + siding option (Split / Safety) | B10: Safety | C10: Split = Alps roof + Baz siding. Safety = Safety Roofing combo (siding, flat roof and skylight).
A11: Construction contingency (% of cost) | B11: 0.1 | C11: Tender Package: 10% budget reserve.
A12: Provisional: structural reinforcement | B12: 5000 | C12: Tender Package P2 provisional / change order risk.

Sheet All Bids
A1: All Manning Bid Requests (from JobTread, Oct 20, 2026)
A2: Amounts are the cost entered on each JobTread bid request. HST treatment not confirmed. To add a bid, insert a row above the last one and copy column E down.
A4: Division | B4: Vendor | C4: Status | D4: Amount ($) | E4: Lookup key (formula) | F4: JobTread #
A5: General Works + Demo | B5: Renomar Inc (Olimpiu) | C5: Approved | D5: 57100 | E5: =IF(AND(C5="Approved",D5>0),A5&"|"&ROUND(D5,2),"") -> General Works + Demo|57100 | F5: 46
A6: General Works + Demo | B6: FV Renovations (Fabiano) | C6: Pending | D6: 0 | E6: =IF(AND(C6="Approved",D6>0),A6&"|"&ROUND(D6,2),"") | F6: 15
A7: Demolition | B7: Doctor Demo (Roman) | C7: Pending | D7: 0 | E7: =IF(AND(C7="Approved",D7>0),A7&"|"&ROUND(D7,2),"") | F7: 10
A8: Demolition | B8: Bradley Demolition | C8: Declined | D8: 0 | E8: =IF(AND(C8="Approved",D8>0),A8&"|"&ROUND(D8,2),"") | F8: 41
A9: Demolition | B9: Universal Impact Services | C9: Declined | D9: 0 | E9: =IF(AND(C9="Approved",D9>0),A9&"|"&ROUND(D9,2),"") | F9: 42
A10: Framing | B10: Aryan | C10: Approved | D10: 14000 | E10: =IF(AND(C10="Approved",D10>0),A10&"|"&ROUND(D10,2),"") -> Framing|14000 | F10: 31
A11: Framing | B11: New Age Construction (Mario) | C11: Pending | D11: 0 | E11: =IF(AND(C11="Approved",D11>0),A11&"|"&ROUND(D11,2),"") | F11: 17
A12: Framing | B12: Bogdan | C12: Declined | D12: 0 | E12: =IF(AND(C12="Approved",D12>0),A12&"|"&ROUND(D12,2),"") | F12: 30
A13: Lumber | B13: RONA (Jonathan) | C13: Approved | D13: 6386.19 | E13: =IF(AND(C13="Approved",D13>0),A13&"|"&ROUND(D13,2),"") -> Lumber|6386.19 | F13: 43
A14: Lumber | B14: Central Fairbank (Bruno) | C14: Approved | D14: 7040 | E14: =IF(AND(C14="Approved",D14>0),A14&"|"&ROUND(D14,2),"") -> Lumber|7040 | F14: 50
A15: Lumber | B15: KOTT (Jon Stark) | C15: Approved | D15: 7208.9 | E15: =IF(AND(C15="Approved",D15>0),A15&"|"&ROUND(D15,2),"") -> Lumber|7208.9 | F15: 45
A16: Flat Roofing | B16: Alps Roofing | C16: Approved | D16: 15700 | E16: =IF(AND(C16="Approved",D16>0),A16&"|"&ROUND(D16,2),"") -> Flat Roofing|15700 | F16: 21
... A34: Hardwood Install (in GW scope) | B34: Reno Factory (Roland) | C34: Approved | D34: 1215 | E34: =IF(AND(C34="Approved",D34>0),A34&"|"&ROUND(D34,2),"") -> Hardwood Install (in GW scope)|1215 | F34: 22
