Workbook

Sheet Summary
B1: 94 MARGARET AVE — PRICE TO DRYWALL
B2: Rachel Milisic | rmilisic@hotmail.com | Stoney Creek (Hamilton), ON | New 2-storey detached, entry level | PalmView Contracting Inc. | Oct 21, 2026
C4: ABOVE-GRADE AREA | D4: PRICE TO DRYWALL | E4: WITH HST | F4: GROSS MARGIN | G4: GROSS PROFIT | H4: PRICE / SF
C5: =D12 -> 2930 | D5: =E37 -> 1759497.9 | E5: =E39 -> 1988232.6 | F5: =G11 -> 0.4 | G5: =F35 -> 674999.15 | H5: =E37/D12 -> 600.51122
C6: Main 1,460 + Second 1,470 | D6: before HST | E6: 13% HST included | F6: on PalmView price | G6: to drywall | H6: above grade
C8: HOUSE SIZE | F8: PRICING INPUTS
C9: Main floor | D9: 1460 | F9: HST | G9: 0.13
C10: Second floor | D10: 1470 | F10: Contingency (on hard cost) | G10: 0.05
F11: TARGET GROSS MARGIN | G11: 0.4
C12: TOTAL ABOVE GRADE (finished) | D12: =D9+D10 -> 2930 | F12: Equals markup on cost of | G12: =G11/(1-G11) -> 0.66666667
C13: Basement (unfinished, not in SF) | D13: 1460 | F13: Edit yellow cells; everything updates.
C14: Two-car garage | D14: 548
B16: DIVISION BREAKDOWN — FIXED PRICE TO DRYWALL
B17: # | C17: Division | D17: Cost | E17: Price | F17: Gross Profit | G17: Price / SF | H17: % of Price
B18: 1 | C18: Permits, Engineering & Soft Costs | D18: ='Division Detail'!$H$15 -> 43800 | E18: =D18/(1-$G$11) -> 73000 | F18: =E18-D18 -> 29200 | G18: =E18/$D$12 -> 24.914676 | H18: =E18/$E$37 -> 0.041489109
B19: 2 | C19: Site Supervision & General Conditions | D19: ='Division Detail'!$H$34 -> 134750 | E19: =D19/(1-$G$11) -> 224583.33 | F19: =E19-D19 -> 89833.333 | G19: =E19/$D$12 -> 76.649602 | H19: =E19/$E$37 -> 0.12764058
B20: 3 | C20: Demolition & Site Preparation | D20: ='Division Detail'!$H$40 -> 35600 | E20: =D20/(1-$G$11) -> 59333.333 | F20: =E20-D20 -> 23733.333 | G20: =E20/$D$12 -> 20.250284 | H20: =E20/$E$37 -> 0.033721742
B21: 4 | C21: Excavation, Backfill & Grading | D21: ='Division Detail'!$H$47 -> 35270 | E21: =D21/(1-$G$11) -> 58783.333 | F21: =E21-D21 -> 23513.333 | G21: =E21/$D$12 -> 20.062571 | H21: =E21/$E$37 -> 0.033409153
B22: 5 | C22: Footings, Foundation & Waterproofing | D22: ='Division Detail'!$H$57 -> 93988 | E22: =D22/(1-$G$11) -> 156646.67 | F22: =E22-D22 -> 62658.667 | G22: =E22/$D$12 -> 53.463026 | H22: =E22/$E$37 -> 0.089029188
B23: 6 | C23: Concrete Slabs | D23: ='Division Detail'!$H$63 -> 29904 | E23: =D23/(1-$G$11) -> 49840 | F23: =E23-D23 -> 19936 | G23: =E23/$D$12 -> 17.010239 | H23: =E23/$E$37 -> 0.028326263
B24: 7 | C24: Framing & Structural Steel | D24: ='Division Detail'!$H$71 -> 181384 | E24: =D24/(1-$G$11) -> 302306.67 | F24: =E24-D24 -> 120922.67 | G24: =E24/$D$12 -> 103.17634 | H24: =E24/$E$37 -> 0.17181417
B25: 8 | C25: Roofing, Soffit, Fascia & Eaves | D25: ='Division Detail'!$H$80 -> 43745 | E25: =D25/(1-$G$11) -> 72908.333 | F25: =E25-D25 -> 29163.333 | G25: =E25/$D$12 -> 24.88339 | H25: =E25/$E$37 -> 0.041437011
B26: 9 | C26: Windows & Exterior Doors | D26: ='Division Detail'!$H$89 -> 32984 | E26: =D26/(1-$G$11) -> 54973.333 | F26: =E26-D26 -> 21989.333 | G26: =E26/$D$12 -> 18.76223 | H26: =E26/$E$37 -> 0.031243762
B27: 10 | C27: Exterior Cladding: Brick, Stone & Stucco | D27: ='Division Detail'!$H$96 -> 162940 | E27: =D27/(1-$G$11) -> 271566.67 | F27: =E27-D27 -> 108626.67 | G27: =E27/$D$12 -> 92.684869 | H27: =E27/$E$37 -> 0.15434328
B28: 11 | C28: Plumbing Rough-In | D28: ='Division Detail'!$H$101 -> 26500 | E28: =D28/(1-$G$11) -> 44166.667 | F28: =E28-D28 -> 17666.667 | G28: =E28/$D$12 -> 15.073948 | H28: =E28/$E$37 -> 0.025101858
B29: 12 | C29: HVAC & Gas Rough-In | D29: ='Division Detail'!$H$106 -> 28500 | E29: =D29/(1-$G$11) -> 47500 | F29: =E29-D29 -> 19000 | G29: =E29/$D$12 -> 16.211604 | H29: =E29/$E$37 -> 0.026996338
B30: 13 | C30: Electrical Rough-In & Service | D30: ='Division Detail'!$H$113 -> 33350 | E30: =D30/(1-$G$11) -> 55583.333 | F30: =E30-D30 -> 22233.333 | G30: =E30/$D$12 -> 18.970421 | H30: =E30/$E$37 -> 0.031590452
B31: 14 | C31: Insulation & Air Sealing | D31: ='Division Detail'!$H$120 -> 22127.5 | E31: =D31/(1-$G$11) -> 36879.167 | F31: =E31-D31 -> 14751.667 | G31: =E31/$D$12 -> 12.586746 | H31: =E31/$E$37 -> 0.020960052
B32: 15 | C32: Drywall (Level 4, unprimed) | D32: ='Division Detail'!$H$124 -> 48692 | E32: =D32/(1-$G$11) -> 81153.333 | F32: =E32-D32 -> 32461.333 | G32: =E32/$D$12 -> 27.697383 | H32: =E32/$E$37 -> 0.046123007
B33: 16 | C33: Site Cleanup & Closeout | D33: ='Division Detail'!$H$131 -> 10750 | E33: =D33/(1-$G$11) -> 17916.667 | F33: =E33-D33 -> 7166.6667 | G33: =E33/$D$12 -> 6.1149033 | H33: =E33/$E$37 -> 0.010182829
B34: 17 | C34: Construction Contingency (5% reserve) | D34: =SUM(D18:D33)*G10 -> 48214.225 | E34: =D34/(1-$G$11) -> 80357.042 | F34: =E34-D34 -> 32142.817 | G34: =E34/$D$12 -> 27.425611 | H34: =E34/$E$37 -> 0.04567044
C35: PALMVIEW FIXED PRICE (40% margin) | D35: =SUM(D18:D34) -> 1012498.7 | E35: =SUM(E18:E34) -> 1687497.9 | F35: =E35-D35 -> 674999.15 | G35: =E35/$D$12 -> 575.93784 | H35: =E35/$E$37 -> 0.95907923
C36: Municipal & Utility Fees — permit, DCs, utilities (at cost, no margin) | D36: ='Division Detail'!$H$138 -> 72000 | E36: =D36 -> 72000 | F36: =E36-D36 -> 0 | G36: =E36/$D$12 -> 24.573379 | H36: =E36/$E$37 -> 0.040920766
C37: TOTAL TO DRYWALL (before HST) | D37: =D35+D36 -> 1084498.7 | E37: =E35+E36 -> 1759497.9 | F37: =E37-D37 -> 674999.15 | G37: =E37/$D$12 -> 600.51122 | H37: =E37/$E$37 -> 1
C38: HST 13% | E38: =E37*G9 -> 228734.72
C39: TOTAL INCLUDING HST | E39: =E37+E38 -> 1988232.6
B41: MARGIN CHECK — PALMVIEW SCOPE (EXCLUDES PASS-THROUGH FEES)
C42: PalmView cost (incl. contingency) | D42: =D35 -> 1012498.7 | F42: 40% margin means 40 cents of every dollar the client pays
C43: PalmView price | D43: =E35 -> 1687497.9 | F43: is gross profit. On cost, that is a 66.7% markup.
C44: Gross profit | D44: =E35-D35 -> 674999.15 | F44: PalmView's standard 35% markup would equal a 25.9% margin.
...

Sheet Division Detail
B1: DIVISION DETAIL — FIXED PRICE TO DRYWALL
B2: Every line item behind the Summary. Blue = quantities and unit costs from the PalmView Cost Index; price = cost ÷ (1 − margin).
B4: Code | C4: Cost Item | D4: Scope Description | E4: Qty | F4: Unit | G4: Unit Cost | H4: Cost | I4: Price
B5: PERMITS, ENGINEERING & SOFT COSTS
B6: 1.002 | C6: City Permit Package | D6: City permit package: zoning review, application forms and submission to City of Hamilton. | E6: 1 | F6: Lump Sum | G6: 15000 | H6: =E6*G6 -> 15000 | I6: =H6/(1-Summary!$G$11) -> 25000
B7: 1.029 | C7: Permit Coordination Fee | D7: Permit coordination with City, designer (Bobicon) and AM Engineering through issuance. | E7: 1 | F7: Lump Sum | G7: 3000 | H7: =E7*G7 -> 3000 | I7: =H7/(1-Summary!$G$11) -> 5000
B8: 1.007 | C8: Engineering (Structural, Mechanical & Heat Loss) | D8: Engineering: structural (steel beams, lintels), HVAC design and heat loss / SB-12 EEDS. | E8: 1 | F8: Lump Sum | G8: 7000 | H8: =E8*G8 -> 7000 | I8: =H8/(1-Summary!$G$11) -> 11666.667
B9: 1.070 | C9: Truss Layout Drawings | D9: Truss layout drawings for hip roof and girder trusses. | E9: 1 | F9: Lump Sum | G9: 1500 | H9: =E9*G9 -> 1500 | I9: =H9/(1-Summary!$G$11) -> 2500
B10: 1.030 | C10: Surveyor Stakeout, Footing Pins & Wall Pins | D10: Surveyor stakeout, footing pins and wall pins. | E10: 1 | F10: Lump Sum | G10: 2200 | H10: =E10*G10 -> 2200 | I10: =H10/(1-Summary!$G$11) -> 3666.6667
B11: 1.031 | C11: As-Built Survey / Survey Revisions | D11: As-built / foundation location survey. | E11: 1 | F11: Lump Sum | G11: 1800 | H11: =E11*G11 -> 1800 | I11: =H11/(1-Summary!$G$11) -> 3000
B12: 1.020 | C12: Site Field Reviews by Engineer | D12: AM Engineering site reviews: servicing inspection and lot grading. | E12: 2 | F12: Each | G12: 1800 | H12: =E12*G12 -> 3600 | I12: =H12/(1-Summary!$G$11) -> 6000
B13: 1.067 | C13: Hazardous Substance Report | D13: Designated substance survey of existing house before demolition (O. Reg. 278/05). | E13: 1 | F13: Lump Sum | G13: 1200 | H13: =E13*G13 -> 1200 | I13: =H13/(1-Summary!$G$11) -> 2000
B14: 1.021 | C14: Tarion Warranty Enrollment | D14: Tarion new home warranty enrolment. | E14: 1 | F14: Lump Sum | G14: 8500 | H14: =E14*G14 -> 8500 | I14: =H14/(1-Summary!$G$11) -> 14166.667
C15: Subtotal — Permits, Engineering & Soft Costs | H15: =SUM(H6:H14) -> 43800 | I15: =SUM(I6:I14) -> 73000
B17: SITE SUPERVISION & GENERAL CONDITIONS
B18: 1.036 | C18: Tree Protection | D18: Tree protection hoarding at City boulevard tree per City of Hamilton requirements. | E18: 1 | F18: Lump Sum | G18: 4500 | H18: =E18*G18 -> 4500 | I18: =H18/(1-Summary!$G$11) -> 7500
B19: 1.040 | C19: Site Supervision & Project Management (Blended Monthly) | D19: Site supervision and project management, 6 months demo through drywall. | E19: 6 | F19: Months | G19: 12000 | H19: =E19*G19 -> 72000 | I19: =H19/(1-Summary!$G$11) -> 120000
B20: 1.042 | C20: Temporary Hoarding & Safety Fences | D20: Temporary construction fence, front and sides. | E20: 160 | F20: Linear Feet | G20: 45 | H20: =E20*G20 -> 7200 | I20: =H20/(1-Summary!$G$11) -> 12000
B21: 1.043 | C21: Temporary Toilet | D21: Temporary toilet, 6 months. | E21: 6 | F21: Months | G21: 250 | H21: =E21*G21 -> 1500 | I21: =H21/(1-Summary!$G$11) -> 2500
B22: 1.044 | C22: Temporary Hydro | D22: Temporary hydro service. | E22: 1 | F22: Lump Sum | G22: 3500 | H22: =E22*G22 -> 3500 | I22: =H22/(1-Summary!$G$11) -> 5833.3333
B23: 1.045 | C23: Temporary Water | D23: Temporary water. | E23: 1 | F23: Lump Sum | G23: 2800 | H23: =E23*G23 -> 2800 | I23: =H23/(1-Summary!$G$11) -> 4666.6667
B24: 1.046 | C24: Temporary Heating (Winter) | D24: Temporary heat, winter months (if schedule falls in winter). | E24: 3 | F24: Months | G24: 2200 | H24: =E24*G24 -> 6600 | I24: =H24/(1-Summary!$G$11) -> 11000
B25: 1.047 | C25: Crane Service (incl. Operator & Rigging) | D25: Crane with operator to set roof trusses, 1 day. | E25: 1 | F25: Days | G25: 2800 | H25: =E25*G25 -> 2800 | I25: =H25/(1-Summary!$G$11) -> 4666.6667
B26: 1.050 | C26: Scaffold Rental | D26: Scaffold rental for masonry and stucco, 4 months. | E26: 4 | F26: Months | G26: 1500 | H26: =E26*G26 -> 6000 | I26: =H26/(1-Summary!$G$11) -> 10000
B27: 1.051 | C27: Waste Disposal / Garbage Bins | D27: Waste bins and disposal, 6 months. | E27: 6 | F27: Months | G27: 1800 | H27: =E27*G27 -> 10800 | I27: =H27/(1-Summary!$G$11) -> 18000
B28: 1.052 | C28: Miscellaneous Supplies & Materials | D28: Miscellaneous supplies and materials. | E28: 1 | F28: Lump Sum | G28: 8000 | H28: =E28*G28 -> 8000 | I28: =H28/(1-Summary!$G$11) -> 13333.333
B29: 1.053 | C29: Safety Supplies | D29: Safety supplies, fall protection, first aid. | E29: 1 | F29: Lump Sum | G29: 3500 | H29: =E29*G29 -> 3500 | I29: =H29/(1-Summary!$G$11) -> 5833.3333
... B33: 1.069 | C33: Line Protection / Utility Locates | D33: Utility locates. | E33: 1 | F33: Lump Sum | G33: 900 | H33: =E33*G33 -> 900 | I33: =H33/(1-Summary!$G$11) -> 1500
C34: Subtotal — Site Supervision & General Conditions | H34: =SUM(H18:H33) -> 134750 | I34: =SUM(I18:I33) -> 224583.33
B36: DEMOLITION & SITE PREPARATION
B37: 1.068 | C37: Environmental Abatement | D37: Provisional environmental abatement allowance for existing house (asbestos/vermiculite). | E37: 1 | F37: Lump Sum | G37: 8000 | H37: =E37*G37 -> 8000 | I37: =H37/(1-Summary!$G$11) -> 13333.333
B38: 2.001 | C38: House Demolition | D38: Demolish existing 1-storey dwelling incl. basement, foundations and rear shed; dispose. | E38: 1300 | F38: Square Foot | G38: 12 | H38: =E38*G38 -> 15600 | I38: =H38/(1-Summary!$G$11) -> 26000
B39: 2.003 | C39: Site Clearing | D39: Site clearing of shrubs, vegetation and stumps within the building and work area. | E39: 1 | F39: Lump Sum | G39: 12000 | H39: =E39*G39 -> 12000 | I39: =H39/(1-Summary!$G$11) -> 20000
C40: Subtotal — Demolition & Site Preparation | H40: =SUM(H37:H39) -> 35600 | I40: =SUM(I37:I39) -> 59333.333
B42: EXCAVATION, BACKFILL & GRADING
B43: 2.019 | C43: Excavation & Ground works | D43: Excavate basement (1,460 SF, BFE 98.55) plus overdig and frost wall trenches; incl. haul-away of excess per index scope. | E43: 600 | F43: Cubic Yard | G43: 22 | H43: =E43*G43 -> 13200 | I43: =H43/(1-Summary!$G$11) -> 22000
B44: 2.070 | C44: Backfill | D44: Backfill foundation walls and frost walls. | E44: 190 | F44: Cubic Yard | G44: 28 | H44: =E44*G44 -> 5320 | I44: =H44/(1-Summary!$G$11) -> 8866.6667
B45: 2.073 | C45: Rough Grading | D45: Rough grading around building per AM Engineering grading plan. | E45: 2500 | F45: Square Foot | G45: 5 | H45: =E45*G45 -> 12500 | I45: =H45/(1-Summary!$G$11) -> 20833.333
B46: 2.071 | C46: Service Trenching | D46: Service trenching for new water and sewer laterals to 1.0 m from building face. | E46: 50 | F46: Linear Feet | G46: 85 | H46: =E46*G46 -> 4250 | I46: =H46/(1-Summary!$G$11) -> 7083.3333
C47: Subtotal — Excavation, Backfill & Grading | H47: =SUM(H43:H46) -> 35270 | I47: =SUM(I43:I46) -> 58783.333
...

Sheet Turnkey Option
B1: TURNKEY OPTION — ENTRY-LEVEL FINISHES TO OCCUPANCY
B2: Not included in the price to drywall. Shown so the client can see the cost to finish with PalmView.
B4: OPTIONAL — COST TO FINISH WITH PALMVIEW (ENTRY LEVEL)
C5: Division | H5: Cost | I5: Price
C6: Mechanical & Electrical Finish | H6: ='Turnkey Option'!$H$28 -> 19000 | I6: ='Turnkey Option'!$I$28 -> 31666.667
C7: Prime & Finish Paint | H7: ='Turnkey Option'!$H$33 -> 14650 | I7: ='Turnkey Option'!$I$33 -> 24416.667
C8: Interior Doors, Trim & Hardware | H8: ='Turnkey Option'!$H$40 -> 35590 | I8: ='Turnkey Option'!$I$40 -> 59316.667
C9: Flooring & Tile | H9: ='Turnkey Option'!$H$50 -> 34354.5 | I9: ='Turnkey Option'!$I$50 -> 57257.5
C10: Stairs & Railings | H10: ='Turnkey Option'!$H$55 -> 9080 | I10: ='Turnkey Option'!$I$55 -> 15133.333
C11: Cabinets & Countertops | H11: ='Turnkey Option'!$H$62 -> 21375 | I11: ='Turnkey Option'!$I$62 -> 35625
C12: Fixtures, Lighting, Glass & Appliances | H12: ='Turnkey Option'!$H$73 -> 30330 | I12: ='Turnkey Option'!$I$73 -> 50550
C13: Exterior Railings, Steps, Driveway & Sod | H13: ='Turnkey Option'!$H$82 -> 25835 | I13: ='Turnkey Option'!$I$82 -> 43058.333
C14: Finishing Supervision, Inspections & Closeout | H14: ='Turnkey Option'!$H$96 -> 84650 | I14: ='Turnkey Option'!$I$96 -> 141083.33
C15: Total optional finishing | H15: =SUM(H6:H14) -> 274864.5 | I15: =SUM(I6:I14) -> 458107.5
C16: Price to drywall (from Summary) | H16: =Summary!D37 -> 1084498.7 | I16: =Summary!E37 -> 1759497.9
C17: TURNKEY TOTAL, ENTRY LEVEL (before HST) | H17: =H15+H16 -> 1359363.2 | I17: =I15+I16 -> 2217605.4
C18: Turnkey price per SF above grade | I18: =I17/Summary!$D$12 -> 756.8619
B22: Code | C22: Cost Item | D22: Scope Description | E22: Qty | F22: Unit | G22: Unit Cost | H22: Cost | I22: Price
B23: MECHANICAL & ELECTRICAL FINISH
B24: 3.037 | C24: Plumbing - Finish & Fixture Set | D24: Plumbing finish and fixture set (fixtures by allowance). | E24: 1 | F24: Lump Sum | G24: 4000 | H24: =E24*G24 -> 4000 | I24: =H24/(1-Summary!$G$11) -> 6666.6667
B25: 3.035 | C25: Gas - Finish & Appliance Connections | D25: Gas finish and appliance connections. | E25: 1 | F25: Lump Sum | G25: 2000 | H25: =E25*G25 -> 2000 | I25: =H25/(1-Summary!$G$11) -> 3333.3333
B26: 3.033 | C26: HVAC - Finish, Equipment Set & Startup | D26: HVAC finish, equipment set and startup. | E26: 1 | F26: Lump Sum | G26: 6000 | H26: =E26*G26 -> 6000 | I26: =H26/(1-Summary!$G$11) -> 10000
B27: 3.040 | C27: Electrical - Finish, Devices & Fixture Hookup | D27: Electrical finish, devices and fixture hookup (fixtures by allowance). | E27: 1 | F27: Lump Sum | G27: 7000 | H27: =E27*G27 -> 7000 | I27: =H27/(1-Summary!$G$11) -> 11666.667
C28: Subtotal — Mechanical & Electrical Finish | H28: =SUM(H24:H27) -> 19000 | I28: =SUM(I24:I27) -> 31666.667
B30: PRIME & FINISH PAINT
B31: 4.002 | C31: Interior Painting - Prime Coat | D31: Interior prime coat, main and 2nd floor. | E31: 2930 | F31: Square Foot | G31: 1.5 | H31: =E31*G31 -> 4395 | I31: =H31/(1-Summary!$G$11) -> 7325
B32: 4.070 | C32: Interior Painting - Finish Coats | D32: Interior finish paint, 2 coats, builder white, main and 2nd floor. | E32: 2930 | F32: Square Foot | G32: 3.5 | H32: =E32*G32 -> 10255 | I32: =H32/(1-Summary!$G$11) -> 17091.667
C33: Subtotal — Prime & Finish Paint | H33: =SUM(H31:H32) -> 14650 | I33: =SUM(I31:I32) -> 24416.667
B35: INTERIOR DOORS, TRIM & HARDWARE
B36: 4.004 | C36: Interior Doors | D36: Interior doors, hollow-core moulded slab, pre-hung, installed. | E36: 22 | F36: Each | G36: 650 | H36: =E36*G36 -> 14300 | I36: =H36/(1-Summary!$G$11) -> 23833.333
B37: 4.006 | C37: Interior Door Hardware | D37: Interior door hardware, entry-level levers. | E37: 22 | F37: Each | G37: 45 | H37: =E37*G37 -> 990 | I37: =H37/(1-Summary!$G$11) -> 1650
B38: 4.008 | C38: Molding Materials | D38: MDF baseboard and casing, paint grade. | E38: 2100 | F38: Linear Feet | G38: 4 | H38: =E38*G38 -> 8400 | I38: =H38/(1-Summary!$G$11) -> 14000
B39: 4.010 | C39: Finish Carpentry (Trim Moldings and doors labour) | D39: Finish carpentry labour, trim install. | E39: 140 | F39: Hours | G39: 85 | H39: =E39*G39 -> 11900 | I39: =H39/(1-Summary!$G$11) -> 19833.333
C40: Subtotal — Interior Doors, Trim & Hardware | H40: =SUM(H36:H39) -> 35590 | I40: =SUM(I36:I39) -> 59316.667
B42: FLOORING & TILE
B43: 4.052 | C43: Flooring Allowance (if applicable) | D43: Flooring allowance: vinyl plank / laminate, main and 2nd floor, supply and install. | E43: 2450 | F43: Square Foot | G43: 8 | H43: =E43*G43 -> 19600 | I43: =H43/(1-Summary!$G$11) -> 32666.667
B44: 4.053 | C44: Tile Allowance (if applicable) | D44: Tile supply allowance: bath/laundry/entry floors, shower and tub walls, backsplash. | E44: 505 | F44: Square Foot | G44: 6 | H44: =E44*G44 -> 3030 | I44: =H44/(1-Summary!$G$11) -> 5050
B45: 4.014 | C45: Tile Installation Labour (general floor & wall) | D45: Tile install labour, floors. | E45: 335 | F45: Square Foot | G45: 15 | H45: =E45*G45 -> 5025 | I45: =H45/(1-Summary!$G$11) -> 8375
B46: 4.013 | C46: Tile Setting Materials (thinset, membrane, backer) | D46: Tile setting materials, floors. | E46: 335 | F46: Square Foot | G46: 8.5 | H46: =E46*G46 -> 2847.5 | I46: =H46/(1-Summary!$G$11) -> 4745.8333
B47: 4.061 | C47: Tile Shower Wall - Install (labour + setting materials) | D47: Tile install, shower and tub walls (labour + setting materials). | E47: 140 | F47: Square Foot | G47: 18 | H47: =E47*G47 -> 2520 | I47: =H47/(1-Summary!$G$11) -> 4200
...

Sheet Schedule
B1: APPROXIMATE SCHEDULE
B2: Week 1 = construction start after permit. Change the yellow start date and every date updates.
B4: Construction start (Week 1, Monday) | E4: 46398
I5: =TEXT($E$4+(I6-1)*7,"mmm d") -> Nov 16 | M5: =TEXT($E$4+(M6-1)*7,"mmm d") -> Dec 14 | Q5: =TEXT($E$4+(Q6-1)*7,"mmm d") -> Jan 11 | U5: =TEXT($E$4+(U6-1)*7,"mmm d") -> Feb 8 | Y5: =TEXT($E$4+(Y6-1)*7,"mmm d") -> Mar 8 | AC5: =TEXT($E$4+(AC6-1)*7,"mmm d") -> Apr 5 | AG5: =TEXT($E$4+(AG6-1)*7,"mmm d") -> May 3 | AK5: =TEXT($E$4+(AK6-1)*7,"mmm d") -> May 31 | AO5: =TEXT($E$4+(AO6-1)*7,"mmm d") -> Jun 28 | AS5: =TEXT($E$4+(AS6-1)*7,"mmm d") -> Jul 26 | AW5: =TEXT($E$4+(AW6-1)*7,"mmm d") -> Aug 23 | BA5: =TEXT($E$4+(BA6-1)*7,"mmm d") -> Sep 20
B6: Phase | C6: Trade | D6: Start Wk | E6: Weeks | F6: End Wk | G6: Start | H6: Finish | I6: -7 | J6: -6 | K6: -5 | L6: -4 | M6: -3 | N6: -2 | O6: -1 | P6: 0 | Q6: 1 | R6: 2 | S6: 3 | T6: 4 | U6: 5 | V6: 6 | W6: 7 | X6: 8 | Y6: 9 | Z6: 10 | AA6: 11 | AB6: 12 | AC6: 13 | AD6: 14 | AE6: 15 | AF6: 16 | AG6: 17 | AH6: 18 | AI6: 19 | AJ6: 20 | AK6: 21 | AL6: 22 | AM6: 23 | AN6: 24 | AO6: 25 | AP6: 26 | AQ6: 27 | AR6: 28 | AS6: 29 | AT6: 30 | AU6: 31 | AV6: 32 | AW6: 33 | AX6: 34 | AY6: 35 | AZ6: 36 | BA6: 37 | BB6: 38 | BC6: 39
B7: PRE-CONSTRUCTION
B8: Permit issuance, utility disconnects, hazardous survey | C8: Owner / PalmView | D8: -7 | E8: 8 | F8: =D8+E8-1 -> 0 | G8: =$E$4+(D8-1)*7 -> 46342 | H8: =$E$4+(F8-1)*7+4 -> 46395
B9: FIXED SCOPE — TO DRYWALL
B10: Site setup, fencing, tree protection | C10: PalmView | D10: 1 | E10: 1 | F10: =D10+E10-1 -> 1 | G10: =$E$4+(D10-1)*7 -> 46398 | H10: =$E$4+(F10-1)*7+4 -> 46402
B11: Abatement (if required) | C11: Abatement | D11: 1 | E11: 1 | F11: =D11+E11-1 -> 1 | G11: =$E$4+(D11-1)*7 -> 46398 | H11: =$E$4+(F11-1)*7+4 -> 46402
B12: Demolition & site clearing | C12: Demolition | D12: 2 | E12: 2 | F12: =D12+E12-1 -> 3 | G12: =$E$4+(D12-1)*7 -> 46405 | H12: =$E$4+(F12-1)*7+4 -> 46416
B13: Stakeout & excavation | C13: Survey / Excavation | D13: 4 | E13: 1 | F13: =D13+E13-1 -> 4 | G13: =$E$4+(D13-1)*7 -> 46419 | H13: =$E$4+(F13-1)*7+4 -> 46423
B14: Footings | C14: Forming | D14: 5 | E14: 1 | F14: =D14+E14-1 -> 5 | G14: =$E$4+(D14-1)*7 -> 46426 | H14: =$E$4+(F14-1)*7+4 -> 46430
B15: Foundation walls | C15: Forming | D15: 6 | E15: 2 | F15: =D15+E15-1 -> 7 | G15: =$E$4+(D15-1)*7 -> 46433 | H15: =$E$4+(F15-1)*7+4 -> 46444
B16: Dampproofing, weeping tile, underground services | C16: Waterproof / Plumber | D16: 8 | E16: 1 | F16: =D16+E16-1 -> 8 | G16: =$E$4+(D16-1)*7 -> 46447 | H16: =$E$4+(F16-1)*7+4 -> 46451
B17: Backfill & rough grade | C17: Excavation | D17: 9 | E17: 1 | F17: =D17+E17-1 -> 9 | G17: =$E$4+(D17-1)*7 -> 46454 | H17: =$E$4+(F17-1)*7+4 -> 46458
B18: Framing & structural steel | C18: Framer / Steel | D18: 10 | E18: 5 | F18: =D18+E18-1 -> 14 | G18: =$E$4+(D18-1)*7 -> 46461 | H18: =$E$4+(F18-1)*7+4 -> 46493
B19: Roof trusses (crane) & sheathing | C19: Framer | D19: 14 | E19: 1 | F19: =D19+E19-1 -> 14 | G19: =$E$4+(D19-1)*7 -> 46489 | H19: =$E$4+(F19-1)*7+4 -> 46493
B20: Roofing: shingles & flat roofs | C20: Roofer | D20: 15 | E20: 2 | F20: =D20+E20-1 -> 16 | G20: =$E$4+(D20-1)*7 -> 46496 | H20: =$E$4+(F20-1)*7+4 -> 46507
B21: Windows & exterior doors | C21: Windows | D21: 15 | E21: 2 | F21: =D21+E21-1 -> 16 | G21: =$E$4+(D21-1)*7 -> 46496 | H21: =$E$4+(F21-1)*7+4 -> 46507
... B29: Drywall complete — fixed scope handover | C29: PalmView | D29: 27 | E29: 1 | F29: =D29+E29-1 -> 27 | G29: =$E$4+(D29-1)*7 -> 46580 | H29: =$E$4+(F29-1)*7+4 -> 46584
B30: OPTIONAL — FINISH TO OCCUPANCY
B31: Prime, trim, doors, stairs & railings | C31: Finish carpentry | D31: 28 | E31: 3 | F31: =D31+E31-1 -> 30 | G31: =$E$4+(D31-1)*7 -> 46587 | H31: =$E$4+(F31-1)*7+4 -> 46605
B32: Cabinets & countertops | C32: Cabinets / Counters | D32: 28 | E32: 4 | F32: =D32+E32-1 -> 31 | G32: =$E$4+(D32-1)*7 -> 46587 | H32: =$E$4+(F32-1)*7+4 -> 46612
B33: Flooring & tile | C33: Flooring / Tile | D33: 30 | E33: 4 | F33: =D33+E33-1 -> 33 | G33: =$E$4+(D33-1)*7 -> 46601 | H33: =$E$4+(F33-1)*7+4 -> 46626
B34: Finish paint | C34: Painter | D34: 33 | E34: 2 | F34: =D34+E34-1 -> 34 | G34: =$E$4+(D34-1)*7 -> 46622 | H34: =$E$4+(F34-1)*7+4 -> 46633
B35: Mechanical & electrical finish, fixtures | C35: Mech / Elec | D35: 34 | E35: 2 | F35: =D35+E35-1 -> 35 | G35: =$E$4+(D35-1)*7 -> 46629 | H35: =$E$4+(F35-1)*7+4 -> 46640
B36: Final grade, driveway, sod | C36: Landscape / Paving | D36: 34 | E36: 3 | F36: =D36+E36-1 -> 36 | G36: =$E$4+(D36-1)*7 -> 46629 | H36: =$E$4+(F36-1)*7+4 -> 46647
B37: Final clean, inspections, occupancy | C37: PalmView / City | D37: 37 | E37: 2 | F37: =D37+E37-1 -> 38 | G37: =$E$4+(D37-1)*7 -> 46650 | H37: =$E$4+(F37-1)*7+4 -> 46661
B38: Deficiencies & handover | C38: PalmView | D38: 39 | E38: 1 | F38: =D38+E38-1 -> 39 | G38: =$E$4+(D38-1)*7 -> 46664 | H38: =$E$4+(F38-1)*7+4 -> 46668
B40: KEY DATES
B41: Construction start | G41: =E4 -> 46398
B42: Foundation complete | G42: =$E$4+8*7+4 -> 46458
B43: Closed in: framed, roofed, windows | G43: =$E$4+15*7+4 -> 46507
B44: DRYWALL COMPLETE — FIXED SCOPE DONE (~6 months) | G44: =$E$4+26*7+4 -> 46584
B45: Occupancy, if finishing is added (~9 months) | G45: =$E$4+38*7+4 -> 46668
