Workbook

Sheet Overview & Margins
B1: 94 MARGARET AVE — ESTIMATE OVERVIEW & MARGINS
B2: PalmView Contracting Inc. | New 2-storey single detached, entry level, fixed price to drywall & prime | Oct 21, 2026
B4: INPUTS
B5: Item | C5: Value | D5: Source / note
B6: HST | C6: 0.13 | D6: Ontario HST
B7: Construction contingency (on Fixed hard cost) | C7: 0.05 | D7: Index default 10%; set to 5% for this job
B8: PalmView standard markup (for comparison) | C8: 0.35 | D8: 9 OH + 6 Profit + 5 Indirect + 15 Markup
B9: TARGET GROSS MARGIN (on sell price) | C9: 0.4 | D9: Raff: 40% margin. Sell = Cost / (1 - margin)
B10: Equivalent markup on cost | C10: =C9/(1-C9) -> 0.66666667 | D10: 40% margin = 66.7% markup
B12: PROJECT & SIZE
B13: Client | C13: Rachel Milisic
B14: Email | C14: rmilisic@hotmail.com
B15: Site | C15: 94 Margaret Ave, Stoney Creek (Hamilton), ON
B16: Drawings | C16: Bobicon Ltd. SP1, A0.1–A6.0 (Apr 9, 2026); AM Eng. Grading Plan 26047 Rev.3 (Sep 30, 2026)
B17: Lot | C17: 82'-6" x 150' (approx. 12,375 SF)
B18: Main floor (SF) | C18: 1460
B19: Second floor (SF) | C19: 1470
B20: Total finished (SF) | C20: =C18+C19 -> 2930
B21: Basement, unfinished (SF) | C21: 1460
B22: Garage (SF) | C22: 548
B23: Front porch / rear covered patio (SF) | C23: 60 / 204
B26: PRICE SUMMARY
B27: Block | C27: Cost | D27: Sell Price | E27: Gross Profit | F27: Margin % | G27: Markup %
B28: 1. Owner Direct (at cost, no margin) | C28: =SUMIFS('Line Items'!$I$2:$I$132,'Line Items'!$A$2:$A$132,"Owner Direct") -> 72000 | D28: =C28 -> 72000 | E28: =D28-C28 -> 0 | F28: =IF(D28=0,0,E28/D28) -> 0 | G28: =IF(C28=0,0,E28/C28) -> 0
B29: 2. Fixed hard cost to drywall & prime | C29: =SUMIFS('Line Items'!$I$2:$I$132,'Line Items'!$A$2:$A$132,"Fixed to Drywall") -> 987679.5 | D29: =C29/(1-$C$9) -> 1646132.5 | E29: =D29-C29 -> 658453 | F29: =IF(D29=0,0,E29/D29) -> 0.4 | G29: =IF(C29=0,0,E29/C29) -> 0.66666667
B30: 2a. Construction contingency | C30: =C29*$C$7 -> 49383.975 | D30: =C30/(1-$C$9) -> 82306.625 | E30: =D30-C30 -> 32922.65 | F30: =IF(D30=0,0,E30/D30) -> 0.4 | G30: =IF(C30=0,0,E30/C30) -> 0.66666667
B31: TOTAL TO DRYWALL (before HST) | C31: =SUM(C28:C30) -> 1109063.5 | D31: =SUM(D28:D30) -> 1800439.1 | E31: =D31-C31 -> 691375.65 | F31: =IF(D31=0,0,E31/D31) -> 0.3840039 | G31: =IF(C31=0,0,E31/C31) -> 0.62338691
B32: 3. Finish allowances, entry level (optional) | C32: =SUMIFS('Line Items'!$I$2:$I$132,'Line Items'!$A$2:$A$132,"Finish Allowance (Optional)") -> 166819.5 | D32: =C32/(1-$C$9) -> 278032.5 | E32: =D32-C32 -> 111213 | F32: =IF(D32=0,0,E32/D32) -> 0.4 | G32: =IF(C32=0,0,E32/C32) -> 0.66666667
B33: 4. Completion to occupancy (optional) | C33: =SUMIFS('Line Items'!$I$2:$I$132,'Line Items'!$A$2:$A$132,"Completion (Optional)") -> 84650 | D33: =C33/(1-$C$9) -> 141083.33 | E33: =D33-C33 -> 56433.333 | F33: =IF(D33=0,0,E33/D33) -> 0.4 | G33: =IF(C33=0,0,E33/C33) -> 0.66666667
B34: TOTAL TURNKEY, ENTRY LEVEL (before HST) | C34: =C31+C32+C33 -> 1360533 | D34: =D31+D32+D33 -> 2219555 | E34: =D34-C34 -> 859021.98 | F34: =IF(D34=0,0,E34/D34) -> 0.38702443 | G34: =IF(C34=0,0,E34/C34) -> 0.63138638
B36: WITH HST
C37: Before HST | D37: HST | E37: Total incl. HST | F37: Sell $/SF finished | G37: Cost $/SF finished
B38: To drywall | C38: =D31 -> 1800439.1 | D38: =C38*$C$6 -> 234057.09 | E38: =C38+D38 -> 2034496.2 | F38: =D31/$C$20 -> 614.48434 | G38: =C31/$C$20 -> 378.51996
B39: Turnkey, entry level | C39: =D34 -> 2219555 | D39: =C39*$C$6 -> 288542.14 | E39: =C39+D39 -> 2508097.1 | F39: =D34/$C$20 -> 757.52729 | G39: =C34/$C$20 -> 464.34573
B41: MARGIN vs. MARKUP — TO DRYWALL
C42: Sell Price | D42: Gross Profit | E42: Margin % | F42: Markup % | G42: Diff vs 40% margin
B43: At 40% target margin (this estimate) | C43: =D31 -> 1800439.1 | D43: =C43-$C$31 -> 691375.65 | E43: =D43/C43 -> 0.3840039 | F43: =D43/$C$31 -> 0.62338691 | G43: =C43-$C$43 -> 0
B44: At PalmView standard 35% markup | C44: =C28+(C29+C30)*(1+$C$8) -> 1472035.7 | D44: =C44-$C$31 -> 362972.22 | E44: =D44/C44 -> 0.24657841 | F44: =D44/$C$31 -> 0.32727813 | G44: =C44-$C$43 -> -328403.43
B45: Margin % and markup % here are measured on the full to-drywall total, including Owner Direct pass-through, so they read slightly lower than the block-level 40%.
B47: SCOPE BASIS
...

Sheet Line Items
A1: Block | B1: Division | C1: Cost Code | D1: Cost Item | E1: Description | F1: Qty | G1: Unit | H1: Unit Cost | I1: Cost | J1: Sell Price | K1: Note
A2: Owner Direct | B2: OD Building Permit Fees | C2: 1.016 | D2: Building Permit Fees | E2: Building permit fees, City of Hamilton (new SFD + grading review). Pass-through at cost. | F2: 1 | G2: Lump Sum | H2: 12000 | I2: =F2*H2 -> 12000 | J2: =I2 -> 12000
A3: Owner Direct | B3: OD Development Charges | C3: 1.034 | D3: Development Charges | E3: Development charges, City of Hamilton. Knock-down-rebuild default; demolition credit to be confirmed. | F3: 1 | G3: Lump Sum | H3: 45000 | I3: =F3*H3 -> 45000 | J3: =I3 -> 45000 | K3: Confirm Hamilton demo credit
A4: Owner Direct | B4: OD Utility Connection Fees | C4: 1.035 | D4: Utility Connection Fees | E4: Utility connection fees bundle: water/sewer permits, gas and hydro service fees. Pass-through at cost. | F4: 1 | G4: Lump Sum | H4: 15000 | I4: =F4*H4 -> 15000 | J4: =I4 -> 15000
A5: Fixed to Drywall | B5: 01 Soft Costs, Permits & Engineering | C5: 1.002 | D5: City Permit Package | E5: City permit package: zoning review, application forms and submission to City of Hamilton. | F5: 1 | G5: Lump Sum | H5: 15000 | I5: =F5*H5 -> 15000 | J5: =I5/(1-'Overview & Margins'!$C$9) -> 25000
A6: Fixed to Drywall | B6: 01 Soft Costs, Permits & Engineering | C6: 1.007 | D6: Engineering (Structural, Mechanical & Heat Loss) | E6: Engineering: structural (steel beams, lintels), HVAC design and heat loss / SB-12 EEDS. | F6: 1 | G6: Lump Sum | H6: 7000 | I6: =F6*H6 -> 7000 | J6: =I6/(1-'Overview & Margins'!$C$9) -> 11666.667
A7: Fixed to Drywall | B7: 01 Soft Costs, Permits & Engineering | C7: 1.020 | D7: Site Field Reviews by Engineer | E7: AM Engineering site reviews: servicing inspection and lot grading. | F7: 2 | G7: Each | H7: 1800 | I7: =F7*H7 -> 3600 | J7: =I7/(1-'Overview & Margins'!$C$9) -> 6000
A8: Fixed to Drywall | B8: 01 Soft Costs, Permits & Engineering | C8: 1.021 | D8: Tarion Warranty Enrollment | E8: Tarion new home warranty enrolment. | F8: 1 | G8: Lump Sum | H8: 8500 | I8: =F8*H8 -> 8500 | J8: =I8/(1-'Overview & Margins'!$C$9) -> 14166.667
A9: Fixed to Drywall | B9: 01 Soft Costs, Permits & Engineering | C9: 1.029 | D9: Permit Coordination Fee | E9: Permit coordination with City, designer (Bobicon) and AM Engineering through issuance. | F9: 1 | G9: Lump Sum | H9: 3000 | I9: =F9*H9 -> 3000 | J9: =I9/(1-'Overview & Margins'!$C$9) -> 5000
A10: Fixed to Drywall | B10: 01 Soft Costs, Permits & Engineering | C10: 1.030 | D10: Surveyor Stakeout, Footing Pins & Wall Pins | E10: Surveyor stakeout, footing pins and wall pins. | F10: 1 | G10: Lump Sum | H10: 2200 | I10: =F10*H10 -> 2200 | J10: =I10/(1-'Overview & Margins'!$C$9) -> 3666.6667
A11: Fixed to Drywall | B11: 01 Soft Costs, Permits & Engineering | C11: 1.031 | D11: As-Built Survey / Survey Revisions | E11: As-built / foundation location survey. | F11: 1 | G11: Lump Sum | H11: 1800 | I11: =F11*H11 -> 1800 | J11: =I11/(1-'Overview & Margins'!$C$9) -> 3000
A12: Fixed to Drywall | B12: 01 Soft Costs, Permits & Engineering | C12: 1.067 | D12: Hazardous Substance Report | E12: Designated substance survey of existing house before demolition (O. Reg. 278/05). | F12: 1 | G12: Lump Sum | H12: 1200 | I12: =F12*H12 -> 1200 | J12: =I12/(1-'Overview & Margins'!$C$9) -> 2000
A13: Fixed to Drywall | B13: 01 Soft Costs, Permits & Engineering | C13: 1.070 | D13: Truss Layout Drawings | E13: Truss layout drawings for hip roof and girder trusses. | F13: 1 | G13: Lump Sum | H13: 1500 | I13: =F13*H13 -> 1500 | J13: =I13/(1-'Overview & Margins'!$C$9) -> 2500
A14: Fixed to Drywall | B14: 02 General Conditions & Site Services | C14: 1.036 | D14: Tree Protection | E14: Tree protection hoarding at City boulevard tree per City of Hamilton requirements. | F14: 1 | G14: Lump Sum | H14: 4500 | I14: =F14*H14 -> 4500 | J14: =I14/(1-'Overview & Margins'!$C$9) -> 7500
A15: Fixed to Drywall | B15: 02 General Conditions & Site Services | C15: 1.040 | D15: Site Supervision & Project Management (Blended Monthly) | E15: Site supervision and project management, 6 months demo through drywall. | F15: 6 | G15: Months | H15: 12000 | I15: =F15*H15 -> 72000 | J15: =I15/(1-'Overview & Margins'!$C$9) -> 120000
A16: Fixed to Drywall | B16: 02 General Conditions & Site Services | C16: 1.042 | D16: Temporary Hoarding & Safety Fences | E16: Temporary construction fence, front and sides. | F16: 160 | G16: Linear Feet | H16: 45 | I16: =F16*H16 -> 7200 | J16: =I16/(1-'Overview & Margins'!$C$9) -> 12000
... A29: Fixed to Drywall | B29: 02 General Conditions & Site Services | C29: 1.069 | D29: Line Protection / Utility Locates | E29: Utility locates. | F29: 1 | G29: Lump Sum | H29: 900 | I29: =F29*H29 -> 900 | J29: =I29/(1-'Overview & Margins'!$C$9) -> 1500
A30: Fixed to Drywall | B30: 03 Abatement, Demolition & Site Clearing | C30: 1.068 | D30: Environmental Abatement | E30: Provisional environmental abatement allowance for existing house (asbestos/vermiculite). | F30: 1 | G30: Lump Sum | H30: 8000 | I30: =F30*H30 -> 8000 | J30: =I30/(1-'Overview & Margins'!$C$9) -> 13333.333 | K30: Provisional until DSS complete
A31: Fixed to Drywall | B31: 03 Abatement, Demolition & Site Clearing | C31: 2.001 | D31: House Demolition | E31: Demolish existing 1-storey dwelling incl. basement, foundations and rear shed; dispose. | F31: 1300 | G31: Square Foot | H31: 12 | I31: =F31*H31 -> 15600 | J31: =I31/(1-'Overview & Margins'!$C$9) -> 26000
A32: Fixed to Drywall | B32: 03 Abatement, Demolition & Site Clearing | C32: 2.003 | D32: Site Clearing | E32: Site clearing of shrubs, vegetation and stumps within the building and work area. | F32: 1 | G32: Lump Sum | H32: 12000 | I32: =F32*H32 -> 12000 | J32: =I32/(1-'Overview & Margins'!$C$9) -> 20000
A33: Fixed to Drywall | B33: 04 Excavation, Backfill & Grading | C33: 2.019 | D33: Excavation & Ground works | E33: Excavate basement (1,460 SF, BFE 98.55) plus overdig and frost wall trenches; incl. haul-away of excess per index scope. | F33: 600 | G33: Cubic Yard | H33: 22 | I33: =F33*H33 -> 13200 | J33: =I33/(1-'Overview & Margins'!$C$9) -> 22000
A34: Fixed to Drywall | B34: 04 Excavation, Backfill & Grading | C34: 2.070 | D34: Backfill | E34: Backfill foundation walls and frost walls. | F34: 190 | G34: Cubic Yard | H34: 28 | I34: =F34*H34 -> 5320 | J34: =I34/(1-'Overview & Margins'!$C$9) -> 8866.6667
A35: Fixed to Drywall | B35: 04 Excavation, Backfill & Grading | C35: 2.071 | D35: Service Trenching | E35: Service trenching for new water and sewer laterals to 1.0 m from building face. | F35: 50 | G35: Linear Feet | H35: 85 | I35: =F35*H35 -> 4250 | J35: =I35/(1-'Overview & Margins'!$C$9) -> 7083.3333
A36: Fixed to Drywall | B36: 04 Excavation, Backfill & Grading | C36: 2.073 | D36: Rough Grading | E36: Rough grading around building per AM Engineering grading plan. | F36: 2500 | G36: Square Foot | H36: 5 | I36: =F36*H36 -> 12500 | J36: =I36/(1-'Overview & Margins'!$C$9) -> 20833.333
A37: Fixed to Drywall | B37: 05 Footings, Foundation & Waterproofing | C37: 2.046 | D37: Footings (Forming, Rebar & Concrete) | E37: Strip footings at basement, garage and patio frost walls plus pad footings, all-in. | F37: 314 | G37: Linear Feet | H37: 70 | I37: =F37*H37 -> 21980 | J37: =I37/(1-'Overview & Margins'!$C$9) -> 36633.333
A38: Fixed to Drywall | B38: 05 Footings, Foundation & Waterproofing | C38: 2.051 | D38: Waterproofing | E38: Bituminous dampproofing and drainage mat on basement walls below grade. | F38: 1360 | G38: Square Foot | H38: 12 | I38: =F38*H38 -> 16320 | J38: =I38/(1-'Overview & Margins'!$C$9) -> 27200
A39: Fixed to Drywall | B39: 05 Footings, Foundation & Waterproofing | C39: 2.053 | D39: Weeping Tile | E39: Weeping tile at basement footing perimeter to sump. | F39: 181 | G39: Linear Feet | H39: 28 | I39: =F39*H39 -> 5068 | J39: =I39/(1-'Overview & Margins'!$C$9) -> 8446.6667
A40: Fixed to Drywall | B40: 05 Footings, Foundation & Waterproofing | C40: 2.058 | D40: Perimeter Drainage 3/4" Crush | E40: 3/4" clear stone cover over weeping tile. | F40: 90 | G40: Ton | H40: 48 | I40: =F40*H40 -> 4320 | J40: =I40/(1-'Overview & Margins'!$C$9) -> 7200
A41: Fixed to Drywall | B41: 05 Footings, Foundation & Waterproofing | C41: 2.080 | D41: Foundation Walls - Poured In Place (8" formed, 3-bar) | E41: Basement foundation walls incl. cold room, approx. 8'-10" high, all-in. Drawings show 10"/12" walls; confirm thickness. | F41: 181 | G41: Linear Feet | H41: 150 | I41: =F41*H41 -> 27150 | J41: =I41/(1-'Overview & Margins'!$C$9) -> 45250
A42: Fixed to Drywall | B42: 05 Footings, Foundation & Waterproofing | C42: 2.080 | D42: Foundation Walls - Poured In Place (8" formed, 3-bar) | E42: Garage and rear patio frost walls (unexcavated areas), all-in. | F42: 113 | G42: Linear Feet | H42: 150 | I42: =F42*H42 -> 16950 | J42: =I42/(1-'Overview & Margins'!$C$9) -> 28250
... A46: Fixed to Drywall | B46: 06 Concrete Slabs | C46: 2.056 | D46: Porch Slabs | E46: Front porch (60 SF) and raised rear covered patio (204 SF) slabs. | F46: 264 | G46: Square Foot | H46: 22 | I46: =F46*H46 -> 5808 | J46: =I46/(1-'Overview & Margins'!$C$9) -> 9680
A47: Fixed to Drywall | B47: 07 Framing & Structural Steel | C47: 3.002 | D47: Framing Materials | E47: Framing materials: house 2,930 SF + garage 548 SF, incl. floors, walls, roof trusses, flat roofs, sheathing. LIVE LUMBER QUOTE REQUIRED. | F47: 3478 | G47: Square Foot | H47: 20 | I47: =F47*H47 -> 69560 | J47: =I47/(1-'Overview & Margins'!$C$9) -> 115933.33 | K47: Lumber volatile - get live quote
A48: Fixed to Drywall | B48: 07 Framing & Structural Steel | C48: 3.006 | D48: Framing Labour | E48: Framing labour, same area. | F48: 3478 | G48: Square Foot | H48: 18 | I48: =F48*H48 -> 62604 | J48: =I48/(1-'Overview & Margins'!$C$9) -> 104340 | K48: Lumber volatile - get live quote
A49: Fixed to Drywall | B49: 07 Framing & Structural Steel | C49: 3.009 | D49: Steel Beams | E49: Steel beams: W10x22 x2 (basement), W8x28, W8x31/W10x22, W8x18 x2, W10x26 (garage). | F49: 7 | G49: Each | H49: 4500 | I49: =F49*H49 -> 31500 | J49: =I49/(1-'Overview & Margins'!$C$9) -> 52500
A50: Fixed to Drywall | B50: 07 Framing & Structural Steel | C50: 3.010 | D50: Steel Posts | E50: Steel posts / columns with base plates. | F50: 5 | G50: Each | H50: 1200 | I50: =F50*H50 -> 6000 | J50: =I50/(1-'Overview & Margins'!$C$9) -> 10000
A51: Fixed to Drywall | B51: 07 Framing & Structural Steel | C51: 3.133 | D51: Back Framing - Whole-House Basis (budget stage) | E51: Back framing, whole-house budget basis (blocking, bulkheads, stair framing). | F51: 2930 | G51: Square Foot | H51: 4 | I51: =F51*H51 -> 11720 | J51: =I51/(1-'Overview & Margins'!$C$9) -> 19533.333
A52: Fixed to Drywall | B52: 08 Roofing, Soffit, Fascia & Eaves | C52: 3.014 | D52: Roofing material & labour (Shingle) | E52: Asphalt shingle hip roof incl. underlayment, ice & water, flashings and roof vents (5/12, approx. 1,850 SF). | F52: 1850 | G52: Square Foot | H52: 8 | I52: =F52*H52 -> 14800 | J52: =I52/(1-'Overview & Margins'!$C$9) -> 24666.667
A53: Fixed to Drywall | B53: 08 Roofing, Soffit, Fascia & Eaves | C53: 3.015 | D53: Torch on install and supply (Flat Roof) | E53: Torch-on flat roof membrane over garage, front porch, rear patio and front roof sections, sloped 2% to scuppers. | F53: 950 | G53: Square Foot | H53: 12 | I53: =F53*H53 -> 11400 | J53: =I53/(1-'Overview & Margins'!$C$9) -> 19000
A54: Fixed to Drywall | B54: 08 Roofing, Soffit, Fascia & Eaves | C54: 3.032 | D54: Flashing and aluminum capping | E54: Aluminum parapet capping and flashing at flat roofs. | F54: 165 | G54: Linear Feet | H54: 45 | I54: =F54*H54 -> 7425 | J54: =I54/(1-'Overview & Margins'!$C$9) -> 12375
A55: Fixed to Drywall | B55: 08 Roofing, Soffit, Fascia & Eaves | C55: 3.069 | D55: Soffits | E55: Prefinished aluminum soffit. | F55: 220 | G55: Linear Feet | H55: 16 | I55: =F55*H55 -> 3520 | J55: =I55/(1-'Overview & Margins'!$C$9) -> 5866.6667
...

Sheet Division Breakdown
A1: 94 MARGARET AVE — DIVISION BREAKDOWN
A2: Cost from Line Items tab; sell at target margin from Overview tab.
A4: BLOCK 1 — OWNER DIRECT (AT COST)
A5: Division | B5: Cost | C5: Sell Price | D5: Gross Profit | E5: % of Block Sell | F5: Sell $/SF finished
A6: OD Building Permit Fees | B6: =SUMIFS('Line Items'!$I$2:$I$132,'Line Items'!$B$2:$B$132,A6) -> 12000 | C6: =B6 -> 12000 | D6: =C6-B6 -> 0 | E6: =IF($C$9=0,0,C6/$C$9) -> 0.16666667 | F6: =C6/'Overview & Margins'!$C$20 -> 4.0955631
A7: OD Development Charges | B7: =SUMIFS('Line Items'!$I$2:$I$132,'Line Items'!$B$2:$B$132,A7) -> 45000 | C7: =B7 -> 45000 | D7: =C7-B7 -> 0 | E7: =IF($C$9=0,0,C7/$C$9) -> 0.625 | F7: =C7/'Overview & Margins'!$C$20 -> 15.358362
A8: OD Utility Connection Fees | B8: =SUMIFS('Line Items'!$I$2:$I$132,'Line Items'!$B$2:$B$132,A8) -> 15000 | C8: =B8 -> 15000 | D8: =C8-B8 -> 0 | E8: =IF($C$9=0,0,C8/$C$9) -> 0.20833333 | F8: =C8/'Overview & Margins'!$C$20 -> 5.1194539
A9: Total Owner Direct | B9: =SUM(B6:B8) -> 72000 | C9: =SUM(C6:C8) -> 72000 | D9: =C9-B9 -> 0 | E9: =IF($C$9=0,0,C9/$C$9) -> 1 | F9: =C9/'Overview & Margins'!$C$20 -> 24.573379
A11: BLOCK 2 — FIXED COST TO DRYWALL & PRIME
A12: Division | B12: Cost | C12: Sell Price | D12: Gross Profit | E12: % of Block Sell | F12: Sell $/SF finished
A13: 01 Soft Costs, Permits & Engineering | B13: =SUMIFS('Line Items'!$I$2:$I$132,'Line Items'!$B$2:$B$132,A13) -> 43800 | C13: =B13/(1-'Overview & Margins'!$C$9) -> 73000 | D13: =C13-B13 -> 29200 | E13: =IF($C$30=0,0,C13/$C$30) -> 0.042234638 | F13: =C13/'Overview & Margins'!$C$20 -> 24.914676
A14: 02 General Conditions & Site Services | B14: =SUMIFS('Line Items'!$I$2:$I$132,'Line Items'!$B$2:$B$132,A14) -> 134750 | C14: =B14/(1-'Overview & Margins'!$C$9) -> 224583.33 | D14: =C14-B14 -> 89833.333 | E14: =IF($C$30=0,0,C14/$C$30) -> 0.12993419 | F14: =C14/'Overview & Margins'!$C$20 -> 76.649602
A15: 03 Abatement, Demolition & Site Clearing | B15: =SUMIFS('Line Items'!$I$2:$I$132,'Line Items'!$B$2:$B$132,A15) -> 35600 | C15: =B15/(1-'Overview & Margins'!$C$9) -> 59333.333 | D15: =C15-B15 -> 23733.333 | E15: =IF($C$30=0,0,C15/$C$30) -> 0.034327696 | F15: =C15/'Overview & Margins'!$C$20 -> 20.250284
A16: 04 Excavation, Backfill & Grading | B16: =SUMIFS('Line Items'!$I$2:$I$132,'Line Items'!$B$2:$B$132,A16) -> 35270 | C16: =B16/(1-'Overview & Margins'!$C$9) -> 58783.333 | D16: =C16-B16 -> 23513.333 | E16: =IF($C$30=0,0,C16/$C$30) -> 0.03400949 | F16: =C16/'Overview & Margins'!$C$20 -> 20.062571
A17: 05 Footings, Foundation & Waterproofing | B17: =SUMIFS('Line Items'!$I$2:$I$132,'Line Items'!$B$2:$B$132,A17) -> 93988 | C17: =B17/(1-'Overview & Margins'!$C$9) -> 156646.67 | D17: =C17-B17 -> 62658.667 | E17: =IF($C$30=0,0,C17/$C$30) -> 0.090628975 | F17: =C17/'Overview & Margins'!$C$20 -> 53.463026
A18: 06 Concrete Slabs | B18: =SUMIFS('Line Items'!$I$2:$I$132,'Line Items'!$B$2:$B$132,A18) -> 29904 | C18: =B18/(1-'Overview & Margins'!$C$9) -> 49840 | D18: =C18-B18 -> 19936 | E18: =IF($C$30=0,0,C18/$C$30) -> 0.028835265 | F18: =C18/'Overview & Margins'!$C$20 -> 17.010239
A19: 07 Framing & Structural Steel | B19: =SUMIFS('Line Items'!$I$2:$I$132,'Line Items'!$B$2:$B$132,A19) -> 181384 | C19: =B19/(1-'Overview & Margins'!$C$9) -> 302306.67 | D19: =C19-B19 -> 120922.67 | E19: =IF($C$30=0,0,C19/$C$30) -> 0.17490154 | F19: =C19/'Overview & Margins'!$C$20 -> 103.17634
A20: 08 Roofing, Soffit, Fascia & Eaves | B20: =SUMIFS('Line Items'!$I$2:$I$132,'Line Items'!$B$2:$B$132,A20) -> 43745 | C20: =B20/(1-'Overview & Margins'!$C$9) -> 72908.333 | D20: =C20-B20 -> 29163.333 | E20: =IF($C$30=0,0,C20/$C$30) -> 0.042181603 | F20: =C20/'Overview & Margins'!$C$20 -> 24.88339
A21: 09 Windows & Exterior Doors | B21: =SUMIFS('Line Items'!$I$2:$I$132,'Line Items'!$B$2:$B$132,A21) -> 32984 | C21: =B21/(1-'Overview & Margins'!$C$9) -> 54973.333 | D21: =C21-B21 -> 21989.333 | E21: =IF($C$30=0,0,C21/$C$30) -> 0.031805189 | F21: =C21/'Overview & Margins'!$C$20 -> 18.76223
A22: 10 Exterior Cladding (Brick, Stone, Stucco) | B22: =SUMIFS('Line Items'!$I$2:$I$132,'Line Items'!$B$2:$B$132,A22) -> 162940 | C22: =B22/(1-'Overview & Margins'!$C$9) -> 271566.67 | D22: =C22-B22 -> 108626.67 | E22: =IF($C$30=0,0,C22/$C$30) -> 0.15711671 | F22: =C22/'Overview & Margins'!$C$20 -> 92.684869
A23: 11 Plumbing | B23: =SUMIFS('Line Items'!$I$2:$I$132,'Line Items'!$B$2:$B$132,A23) -> 30500 | C23: =B23/(1-'Overview & Margins'!$C$9) -> 50833.333 | D23: =C23-B23 -> 20333.333 | E23: =IF($C$30=0,0,C23/$C$30) -> 0.029409965 | F23: =C23/'Overview & Margins'!$C$20 -> 17.349261
A24: 12 HVAC & Gas | B24: =SUMIFS('Line Items'!$I$2:$I$132,'Line Items'!$B$2:$B$132,A24) -> 36500 | C24: =B24/(1-'Overview & Margins'!$C$9) -> 60833.333 | D24: =C24-B24 -> 24333.333 | E24: =IF($C$30=0,0,C24/$C$30) -> 0.035195531 | F24: =C24/'Overview & Margins'!$C$20 -> 20.76223
... A28: 16 Closeout (at Drywall) | B28: =SUMIFS('Line Items'!$I$2:$I$132,'Line Items'!$B$2:$B$132,A28) -> 10750 | C28: =B28/(1-'Overview & Margins'!$C$9) -> 17916.667 | D28: =C28-B28 -> 7166.6667 | E28: =IF($C$30=0,0,C28/$C$30) -> 0.010365807 | F28: =C28/'Overview & Margins'!$C$20 -> 6.1149033
A29: 17 Construction Contingency | B29: ='Overview & Margins'!C30 -> 49383.975 | C29: =B29/(1-'Overview & Margins'!$C$9) -> 82306.625 | D29: =C29-B29 -> 32922.65 | E29: =IF($C$30=0,0,C29/$C$30) -> 0.047619048 | F29: =C29/'Overview & Margins'!$C$20 -> 28.090998
A30: Total Fixed to Drywall | B30: =SUM(B13:B29) -> 1037063.5 | C30: =SUM(C13:C29) -> 1728439.1 | D30: =C30-B30 -> 691375.65 | E30: =IF($C$30=0,0,C30/$C$30) -> 1 | F30: =C30/'Overview & Margins'!$C$20 -> 589.91096
A32: TOTAL TO DRYWALL (before HST) | B32: =B9+B30 -> 1109063.5 | C32: =C9+C30 -> 1800439.1 | D32: =C32-B32 -> 691375.65
A34: BLOCK 3 — FINISH ALLOWANCES, ENTRY LEVEL (OPTIONAL)
A35: Division | B35: Cost | C35: Sell Price | D35: Gross Profit | E35: % of Block Sell | F35: Sell $/SF finished
A36: F1 Interior Paint (Finish Coats) | B36: =SUMIFS('Line Items'!$I$2:$I$132,'Line Items'!$B$2:$B$132,A36) -> 10255 | C36: =B36/(1-'Overview & Margins'!$C$9) -> 17091.667 | D36: =C36-B36 -> 6836.6667 | E36: =IF($C$43=0,0,C36/$C$43) -> 0.061473629 | F36: =C36/'Overview & Margins'!$C$20 -> 5.8333333
A37: F2 Interior Doors, Trim & Hardware | B37: =SUMIFS('Line Items'!$I$2:$I$132,'Line Items'!$B$2:$B$132,A37) -> 35590 | C37: =B37/(1-'Overview & Margins'!$C$9) -> 59316.667 | D37: =C37-B37 -> 23726.667 | E37: =IF($C$43=0,0,C37/$C$43) -> 0.21334436 | F37: =C37/'Overview & Margins'!$C$20 -> 20.244596
A38: F3 Flooring & Tile | B38: =SUMIFS('Line Items'!$I$2:$I$132,'Line Items'!$B$2:$B$132,A38) -> 34354.5 | C38: =B38/(1-'Overview & Margins'!$C$9) -> 57257.5 | D38: =C38-B38 -> 22903 | E38: =IF($C$43=0,0,C38/$C$43) -> 0.20593815 | F38: =C38/'Overview & Margins'!$C$20 -> 19.541809
A39: F4 Stairs & Railings | B39: =SUMIFS('Line Items'!$I$2:$I$132,'Line Items'!$B$2:$B$132,A39) -> 9080 | C39: =B39/(1-'Overview & Margins'!$C$9) -> 15133.333 | D39: =C39-B39 -> 6053.3333 | E39: =IF($C$43=0,0,C39/$C$43) -> 0.054430088 | F39: =C39/'Overview & Margins'!$C$20 -> 5.1649602
A40: F5 Cabinets & Countertops | B40: =SUMIFS('Line Items'!$I$2:$I$132,'Line Items'!$B$2:$B$132,A40) -> 21375 | C40: =B40/(1-'Overview & Margins'!$C$9) -> 35625 | D40: =C40-B40 -> 14250 | E40: =IF($C$43=0,0,C40/$C$43) -> 0.1281325 | F40: =C40/'Overview & Margins'!$C$20 -> 12.158703
A41: F6 Fixtures, Lighting, Glass & Appliances | B41: =SUMIFS('Line Items'!$I$2:$I$132,'Line Items'!$B$2:$B$132,A41) -> 30330 | C41: =B41/(1-'Overview & Margins'!$C$9) -> 50550 | D41: =C41-B41 -> 20220 | E41: =IF($C$43=0,0,C41/$C$43) -> 0.18181328 | F41: =C41/'Overview & Margins'!$C$20 -> 17.25256
A42: F7 Exterior Railings, Steps, Driveway & Sod | B42: =SUMIFS('Line Items'!$I$2:$I$132,'Line Items'!$B$2:$B$132,A42) -> 25835 | C42: =B42/(1-'Overview & Margins'!$C$9) -> 43058.333 | D42: =C42-B42 -> 17223.333 | E42: =IF($C$43=0,0,C42/$C$43) -> 0.15486799 | F42: =C42/'Overview & Margins'!$C$20 -> 14.695677
A43: Total Finish Allowances | B43: =SUM(B36:B42) -> 166819.5 | C43: =SUM(C36:C42) -> 278032.5 | D43: =C43-B43 -> 111213 | E43: =IF($C$43=0,0,C43/$C$43) -> 1 | F43: =C43/'Overview & Margins'!$C$20 -> 94.891638
A45: COMPLETION TO OCCUPANCY (OPTIONAL)
A46: Division | B46: Cost | C46: Sell Price | D46: Gross Profit | E46: % of Block Sell | F46: Sell $/SF finished
A47: C1 Completion to Occupancy | B47: =SUMIFS('Line Items'!$I$2:$I$132,'Line Items'!$B$2:$B$132,A47) -> 84650 | C47: =B47/(1-'Overview & Margins'!$C$9) -> 141083.33 | D47: =C47-B47 -> 56433.333 | E47: =IF($C$48=0,0,C47/$C$48) -> 1 | F47: =C47/'Overview & Margins'!$C$20 -> 48.151308
A48: Total Completion | B48: =SUM(B47:B47) -> 84650 | C48: =SUM(C47:C47) -> 141083.33 | D48: =C48-B48 -> 56433.333 | E48: =IF($C$48=0,0,C48/$C$48) -> 1 | F48: =C48/'Overview & Margins'!$C$20 -> 48.151308
...

Sheet Schedule
A1: 94 MARGARET AVE — APPROXIMATE SCHEDULE
A2: Construction start (Week 1, Monday): | C2: 46398 | E2: Assumes permit issued and services disconnected before Week 1. Weather, inspections and selections can move dates.
H3: =TEXT($C$2+(H4-1)*7,"mmm") -> Nov | L3: =TEXT($C$2+(L4-1)*7,"mmm") -> Dec | P3: =TEXT($C$2+(P4-1)*7,"mmm") -> Jan | T3: =TEXT($C$2+(T4-1)*7,"mmm") -> Feb | X3: =TEXT($C$2+(X4-1)*7,"mmm") -> Mar | AB3: =TEXT($C$2+(AB4-1)*7,"mmm") -> Apr | AF3: =TEXT($C$2+(AF4-1)*7,"mmm") -> May | AJ3: =TEXT($C$2+(AJ4-1)*7,"mmm") -> May | AN3: =TEXT($C$2+(AN4-1)*7,"mmm") -> Jun | AR3: =TEXT($C$2+(AR4-1)*7,"mmm") -> Jul | AV3: =TEXT($C$2+(AV4-1)*7,"mmm") -> Aug | AZ3: =TEXT($C$2+(AZ4-1)*7,"mmm") -> Sep
A4: Phase | B4: Trade / By | C4: Start Wk | D4: Weeks | E4: End Wk | F4: Start Date | G4: End Date | H4: -7 | I4: -6 | J4: -5 | K4: -4 | L4: -3 | M4: -2 | N4: -1 | O4: 0 | P4: 1 | Q4: 2 | R4: 3 | S4: 4 | T4: 5 | U4: 6 | V4: 7 | W4: 8 | X4: 9 | Y4: 10 | Z4: 11 | AA4: 12 | AB4: 13 | AC4: 14 | AD4: 15 | AE4: 16 | AF4: 17 | AG4: 18 | AH4: 19 | AI4: 20 | AJ4: 21 | AK4: 22 | AL4: 23 | AM4: 24 | AN4: 25 | AO4: 26 | AP4: 27 | AQ4: 28 | AR4: 29 | AS4: 30 | AT4: 31 | AU4: 32 | AV4: 33 | AW4: 34 | AX4: 35 | AY4: 36 | AZ4: 37 | BA4: 38 | BB4: 39
A5: PRE-CONSTRUCTION
A6: Permit issuance, utility disconnects, hazardous materials survey | B6: Owner / PalmView | C6: -7 | D6: 8 | E6: =C6+D6-1 -> 0 | F6: =$C$2+(C6-1)*7 -> 46342 | G6: =$C$2+(E6-1)*7+4 -> 46395
A7: FIXED SCOPE — TO DRYWALL
A8: Site setup, fencing, tree protection | B8: PalmView | C8: 1 | D8: 1 | E8: =C8+D8-1 -> 1 | F8: =$C$2+(C8-1)*7 -> 46398 | G8: =$C$2+(E8-1)*7+4 -> 46402
A9: Abatement (if required) | B9: Abatement sub | C9: 1 | D9: 1 | E9: =C9+D9-1 -> 1 | F9: =$C$2+(C9-1)*7 -> 46398 | G9: =$C$2+(E9-1)*7+4 -> 46402
A10: Demolition & site clearing | B10: Demo sub | C10: 2 | D10: 2 | E10: =C10+D10-1 -> 3 | F10: =$C$2+(C10-1)*7 -> 46405 | G10: =$C$2+(E10-1)*7+4 -> 46416
A11: Stakeout & excavation | B11: Surveyor / Excavator | C11: 4 | D11: 1 | E11: =C11+D11-1 -> 4 | F11: =$C$2+(C11-1)*7 -> 46419 | G11: =$C$2+(E11-1)*7+4 -> 46423
A12: Footings | B12: Forming sub | C12: 5 | D12: 1 | E12: =C12+D12-1 -> 5 | F12: =$C$2+(C12-1)*7 -> 46426 | G12: =$C$2+(E12-1)*7+4 -> 46430
A13: Foundation walls | B13: Forming sub | C13: 6 | D13: 2 | E13: =C13+D13-1 -> 7 | F13: =$C$2+(C13-1)*7 -> 46433 | G13: =$C$2+(E13-1)*7+4 -> 46444
A14: Dampproofing, weeping tile, underground plumbing & services | B14: Waterproofer / Plumber | C14: 8 | D14: 1 | E14: =C14+D14-1 -> 8 | F14: =$C$2+(C14-1)*7 -> 46447 | G14: =$C$2+(E14-1)*7+4 -> 46451
A15: Backfill & rough grade | B15: Excavator | C15: 9 | D15: 1 | E15: =C15+D15-1 -> 9 | F15: =$C$2+(C15-1)*7 -> 46454 | G15: =$C$2+(E15-1)*7+4 -> 46458
A16: Framing: floors, walls, 2nd floor, steel | B16: Framer / Steel | C16: 10 | D16: 5 | E16: =C16+D16-1 -> 14 | F16: =$C$2+(C16-1)*7 -> 46461 | G16: =$C$2+(E16-1)*7+4 -> 46493
A17: Roof trusses (crane) & sheathing | B17: Framer | C17: 14 | D17: 1 | E17: =C17+D17-1 -> 14 | F17: =$C$2+(C17-1)*7 -> 46489 | G17: =$C$2+(E17-1)*7+4 -> 46493
A18: Roofing: shingles & flat roofs | B18: Roofer | C18: 15 | D18: 2 | E18: =C18+D18-1 -> 16 | F18: =$C$2+(C18-1)*7 -> 46496 | G18: =$C$2+(E18-1)*7+4 -> 46507
A19: Windows & exterior doors | B19: Window sub | C19: 15 | D19: 2 | E19: =C19+D19-1 -> 16 | F19: =$C$2+(C19-1)*7 -> 46496 | G19: =$C$2+(E19-1)*7+4 -> 46507
... A27: Prime coat & drywall turnover | B27: Painter | C27: 27 | D27: 1 | E27: =C27+D27-1 -> 27 | F27: =$C$2+(C27-1)*7 -> 46580 | G27: =$C$2+(E27-1)*7+4 -> 46584
A28: OPTIONAL — FINISH TO OCCUPANCY
A29: Trim, interior doors, stairs & railings | B29: Finish carpenter | C29: 28 | D29: 3 | E29: =C29+D29-1 -> 30 | F29: =$C$2+(C29-1)*7 -> 46587 | G29: =$C$2+(E29-1)*7+4 -> 46605
A30: Cabinets & countertops (template to install) | B30: Cabinet / Counter | C30: 28 | D30: 4 | E30: =C30+D30-1 -> 31 | F30: =$C$2+(C30-1)*7 -> 46587 | G30: =$C$2+(E30-1)*7+4 -> 46612
A31: Flooring & tile | B31: Flooring / Tile | C31: 30 | D31: 4 | E31: =C31+D31-1 -> 33 | F31: =$C$2+(C31-1)*7 -> 46601 | G31: =$C$2+(E31-1)*7+4 -> 46626
A32: Finish paint | B32: Painter | C32: 33 | D32: 2 | E32: =C32+D32-1 -> 34 | F32: =$C$2+(C32-1)*7 -> 46622 | G32: =$C$2+(E32-1)*7+4 -> 46633
A33: Mechanical & electrical finish, fixtures, appliances | B33: Trades | C33: 34 | D33: 2 | E33: =C33+D33-1 -> 35 | F33: =$C$2+(C33-1)*7 -> 46629 | G33: =$C$2+(E33-1)*7+4 -> 46640
A34: Final grade, driveway, sod | B34: Landscaper / Paver | C34: 34 | D34: 3 | E34: =C34+D34-1 -> 36 | F34: =$C$2+(C34-1)*7 -> 46629 | G34: =$C$2+(E34-1)*7+4 -> 46647
A35: Final clean, inspections, occupancy | B35: PalmView / City | C35: 37 | D35: 2 | E35: =C35+D35-1 -> 38 | F35: =$C$2+(C35-1)*7 -> 46650 | G35: =$C$2+(E35-1)*7+4 -> 46661
A36: Deficiencies & handover | B36: PalmView | C36: 39 | D36: 1 | E36: =C36+D36-1 -> 39 | F36: =$C$2+(C36-1)*7 -> 46664 | G36: =$C$2+(E36-1)*7+4 -> 46668
A38: MILESTONES
A39: Construction start | F39: =C2 -> 46398
A40: Foundation complete (end Wk 9) | F40: =$C$2+8*7+4 -> 46458
A41: Framed & roofed, closed in (end Wk 16) | F41: =$C$2+15*7+4 -> 46507
A42: Drywall & prime complete — FIXED SCOPE DONE (end Wk 27) | F42: =$C$2+26*7+4 -> 46584
A43: Occupancy if finishing included (end Wk 39) | F43: =$C$2+38*7+4 -> 46668
A45: Fixed scope to drywall: about 27 weeks (approx. 6 months, matching 6 months of supervision carried). Finishing adds about 12 weeks.
