Workbook

Sheet Summary
A1: 38 Harewood Ave — Second Floor, Porch & Beam | Internal Margin Model
A2: Julianne & David Lee · PalmView Contracting Inc. · Prepared Oct 16, 2026 · INTERNAL — DO NOT SEND TO CLIENT · Blue text = editable input
A4: PROJECT INPUTS
A5: Input | B5: Value | D5: Source / note
A6: Construction start date | B6: 46524 | D6: Joist 110-351 schedule (~May 17, 2027). Change here — schedule updates automatically.
A7: Duration (weeks) | B7: =Schedule!C16 -> 24 | D7: Linked to Schedule tab (sum of phases). Edit phase weeks there.
A8: Substantial completion (est.) | B8: =B6+B7*7-3 -> 46689 | D8: Start + duration, ending on a Friday.
A9: Duration (months, approx.) | B9: =B7/4.33 -> 5.5427252
A10: Option A contract price (pre-HST) | B10: 271379.75 | D10: Joist estimate 110-351: Section 2.0 $269,754.25 + service fee $1,625.50.
A11: Beam & posts price (pre-HST) | B11: 16500 | D11: Recommended price to client for main-floor beam/posts only.
A12: HST rate | B12: 0.13 | D12: Ontario HST.
A13: FV Renovations — general trades (2nd floor + porch) | B13: 37500 | D13: Per Raff: $35K–$40K. Midpoint used. Get FV's written A-only price.
A14: Project management ($/week) | B14: 1700 | D14: Sean's budgeting sheet rate.
A15: Site labour ($/week) | B15: 600 | D15: Sean's budgeting sheet rate.
A16: Overhead ($/week) | B16: 1000 | D16: Per Raff: insurance, WSIB, office, vehicles, software.
A18: PROFIT SUMMARY (BASE — NO OFFERS)
A19: Line | B19: Amount | C19: % of price | D19: How it's calculated
A20: Option A contract (2nd floor, bath, porch) | B20: =B10 -> 271379.75 | C20: =IF($B$22=0,0,B20/$B$22) -> 0.9426844 | D20: Joist 110-351
A21: Beam & posts | B21: =B11 -> 16500 | C21: =IF($B$22=0,0,B21/$B$22) -> 0.057315598 | D21: Input
A22: CONTRACT PRICE (pre-HST) | B22: =B20+B21 -> 287879.75 | C22: =IF($B$22=0,0,B22/$B$22) -> 1
A23: HST | B23: =B22*B12 -> 37424.368 | C23: =IF($B$22=0,0,B23/$B$22) -> 0.13
A24: CLIENT TOTAL (incl. HST) | B24: =B22+B23 -> 325304.12 | C24: =IF($B$22=0,0,B24/$B$22) -> 1.13
A25: Hard cost — 2nd floor & porch | B25: =Costs!E36 -> 184501 | C25: =IF($B$22=0,0,B25/$B$22) -> 0.64089607 | D25: Costs tab
A26: Beam & posts — added cost | B26: =Costs!E46 -> 8200 | C26: =IF($B$22=0,0,B26/$B$22) -> 0.028484115 | D26: Costs tab
A27: Project management | B27: =B14*B7 -> 40800 | C27: =IF($B$22=0,0,B27/$B$22) -> 0.14172584 | D27: Rate × weeks
A28: Site labour | B28: =B15*B7 -> 14400 | C28: =IF($B$22=0,0,B28/$B$22) -> 0.050020885 | D28: Rate × weeks
A29: Overhead | B29: =B16*B7 -> 24000 | C29: =IF($B$22=0,0,B29/$B$22) -> 0.083368142 | D29: Rate × weeks
A30: TOTAL COST | B30: =SUM(B25:B29) -> 271901 | C30: =IF($B$22=0,0,B30/$B$22) -> 0.94449505
A31: NET PROFIT | B31: =B22-B30 -> 15978.75 | C31: =IF($B$22=0,0,B31/$B$22) -> 0.055504946
A32: Margin (profit ÷ price) | B32: =IF(B22=0,0,B31/B22) -> 0.055504946
A33: Markup (profit ÷ cost) | B33: =IF(B30=0,0,B31/B30) -> 0.058766794
A34: Weekly carrying cost (PM + labour + overhead) | B34: =B14+B15+B16 -> 3300 | D34: Every extra week costs this
A36: WITH SELECTED OFFERS, UPSELLS & COST SAVINGS (Offers tab — set Y/N)
A37: Line | B37: Amount | C37: % of price | D37: Note
A38: Price change from selected items | B38: =Offers!H29 -> 0 | C38: =IF($B$40=0,0,B38/$B$40) -> 0
A39: Cost change from selected items | B39: =Offers!I29 -> 7500 | C39: =IF($B$40=0,0,B39/$B$40) -> 0.026052545
A40: ADJUSTED CONTRACT PRICE (pre-HST) | B40: =B22+B38 -> 287879.75 | C40: =IF($B$40=0,0,B40/$B$40) -> 1
A41: ADJUSTED TOTAL COST | B41: =B30+B39 -> 279401 | C41: =IF($B$40=0,0,B41/$B$40) -> 0.9705476
A42: ADJUSTED NET PROFIT | B42: =B40-B41 -> 8478.75 | C42: =IF($B$40=0,0,B42/$B$40) -> 0.029452402
A43: Adjusted margin | B43: =IF(B40=0,0,B42/B40) -> 0.029452402
...

Sheet Costs
A1: Cost Breakdown — All PalmView Costs
A2: Bids = approved JobTread bids on job #6 'Harewood Avenue: Home Addition'. Blue = editable. Finish materials are client-supplied (see Exclusions).
A4: # | B4: Category | C4: Item | D4: Source | E4: Cost ($) | F4: Notes
A5: 1 | B5: General conditions | C5: Temporary hoarding & safety fencing | D5: Internal estimate | E5: 3000
A6: 2 | B6: General conditions | C6: Temporary toilet & temporary hydro | D6: Internal estimate | E6: 3500
A7: 3 | B7: General conditions | C7: Misc. supplies, materials & garbage | D7: Internal estimate | E7: 2000 | F7: FV bid includes the disposal bin.
A8: 4 | B8: General conditions | C8: Safety supplies & third-party inspections | D8: Internal estimate | E8: 2500
A9: 5 | B9: General conditions | C9: Scaffold / lift rental | D9: Allowance | E9: 2500 | F9: Second-floor exterior work.
A10: 6 | B10: General conditions | C10: Weather protection while roof is off | D10: Allowance | E10: 1500 | F10: Tarps, temporary roof.
A11: 7 | B11: General conditions | C11: Engineer field reviews | D11: Allowance | E11: 1500 | F11: Piers, framing per S1.01.
A12: 8 | B12: Porch | C12: Concrete piers (porch) | D12: Per Raff | E12: 2000 | F12: Pier bids pending in JobTread.
A13: 9 | B13: Porch | C13: PT framing, decking & railing material | D13: Allowance | E13: 3500 | F13: Framer bid is labour only.
A14: 10 | B14: Porch | C14: T&G porch ceiling | D14: Allowance | E14: 1200
A15: 11 | B15: Structure | C15: Lumber package (framing, LVLs, sheathing, hardware) | D15: KOTT bid | E15: 10849 | F15: RONA $9,792 also approved.
A16: 12 | B16: Structure | C16: Framing labour (shoring, porch, 2nd floor, roof, beam install) | D16: Built By BC bid | E16: 18500 | F16: Aryan $18,000 / Bogdan $29,000.
A17: 13 | B17: Exterior | C17: Roofing — IKO Cambridge, 2nd floor + porch | D17: Infinity Gutters bid | E17: 6175 | F17: CA Roofing $3,800 available (Offers tab).
A18: 14 | B18: Exterior | C18: Aluminum — soffit, fascia, eaves, capping, flashing band | D18: Infinity Gutters bid | E18: 8325 | F18: CA Roofing $3,800 available (Offers tab).
A19: 15 | B19: Exterior | C19: Wrap, R5 rigid, Kaycan siding, Maibec, brackets, lattice | D19: Infinity Gutters bid | E19: 36000
A20: 16 | B20: Exterior | C20: Windows — 6 units, supply & install | D20: JS Windows bid | E20: 5545 | F20: Welda $5,221 available. Confirm Joist supply vs. exclusion.
A21: 17 | B21: Mechanical | C21: HVAC — 2nd floor, basement, main-floor diffusers, bath fan | D21: MiTech HVAC bid | E21: 8400 | F21: Ideal $12,398 / Sentral $13,479 — risk if MiTech drops.
A22: 18 | B22: Mechanical | C22: Furnace / water heater re-vent (chimney removed) | D22: Allowance | E22: 2000 | F22: Confirm on site whether they vent through chimney.
A23: 19 | B23: Electrical | C23: 200A service, mast, panel, Toronto Hydro, ESA | D23: FV Renovations bid | E23: 4500
A24: 20 | B24: General trades | C24: FV — demo, plumbing, electrical, wall insulation, drywall, paint, carpentry, full bathroom | D24: Per Raff (Summary B13) | E24: =Summary!B13 -> 37500 | F24: Linked to Summary input. FV full A+B bid was $78,000.
A25: 21 | B25: Insulation | C25: Attic R60 blown-in + baffles | D25: FoamIt bid | E25: 2337
A26: 22 | B26: Bathroom | C26: Waterproofing & tile setting materials | D26: Allowance | E26: 1200 | F26: Tile itself is client-supplied.
A27: 23 | B27: Bathroom | C27: Quartz shower curb jamb | D27: Allowance | E27: 400
A28: 24 | B28: Finishes | C28: Engineered hardwood install — 2nd floor (~600 sf) | D28: Reno Factory bid (pro-rated) | E28: 2250 | F28: Bid was $3,000 for both floors.
A29: 25 | B29: Finishes | C29: Stair capping — treads, risers, oak caps, posts, rail, pickets | D29: Per Raff | E29: 5000
A30: 26 | B30: Finishes | C30: Stair stain & varnish (one-tone) | D30: Reno Factory bid | E30: 6370
A31: 27 | B31: Finishes | C31: Aria vents | D31: Internal estimate | E31: 650
A32: 28 | B32: Finishes | C32: Closet install — 2 IKEA PAX (client-supplied) | D32: Allowance | E32: 800
A33: 29 | B33: Completion | C33: Final clean, deficiencies, final inspections | D33: Internal estimate | E33: 4500
C36: HARD COST TOTAL — 2nd floor & porch | E36: =SUM(E5:E33) -> 184501
A38: BEAM & POSTS — ADDED COST (LVL + framing labour already in KOTT and Built By BC bids)
A39: # | B39: Category | C39: Item | D39: Source | E39: Cost ($) | F39: Notes
A40: 1 | B40: Beam | C40: Selective demo of wall section + disposal | D40: Allowance | E40: 1200
A41: 2 | B41: Beam | C41: Basement footing pads + posts | D41: Allowance | E41: 3000 | F41: Only if the engineer requires. Set to 0 if not.
A42: 3 | B42: Beam | C42: Electrical relocation out of wall | D42: Allowance | E42: 800
A43: 4 | B43: Beam | C43: Drywall close-in & beam wrap, Level 4, primed | D43: Allowance | E43: 1500
A44: 5 | B44: Beam | C44: Floor patch at old wall line | D44: Allowance | E44: 1000
...

Sheet Offers
A1: Offers, Bargaining Chips, Upsells & Cost Savings
A2: Set column G to Y to include an item — Summary rows 38–45 update. Price/cost figures for upsells are estimates; confirm with trades before quoting.
A4: Airbnb / rental rate ($/month) | C4: 4500 | D4: Furnished 3-bed near Cliffcrest/Bluffs: ~$4,000–$5,500/mo (REW, liv.rent, Oct 2026)
A5: Months of rental covered | C5: 3
A6: Move-out credit ($/month, capped) | C6: 2500
A7: Price discount (%) | C7: 0.02
A9: Type | B9: Item | C9: Price to client | D9: Cost to PalmView | E9: Profit impact | F9: Margin if only this | G9: Include? (Y/N) | H9: Price applied | I9: Cost applied | J9: Notes
A10: Bargaining chip | B10: Move-out credit (capped, tied to signing + vacant start) | C10: 0 | D10: =C6*C5 -> 7500 | E10: =C10-D10 -> -7500 | F10: =IF((Summary!$B$22+C10)=0,0,(Summary!$B$31+E10)/(Summary!$B$22+C10)) -> 0.029452402 | G10: Y | H10: =IF(G10="Y",C10,0) -> 0 | I10: =IF(G10="Y",D10,0) -> 7500 | J10: Recommended closer.
A11: Bargaining chip | B11: Airbnb / short-term rental covered | C11: 0 | D11: =C4*C5 -> 13500 | E11: =C11-D11 -> -13500 | F11: =IF((Summary!$B$22+C11)=0,0,(Summary!$B$31+E11)/(Summary!$B$22+C11)) -> 0.008610366 | G11: N | H11: =IF(G11="Y",C11,0) -> 0 | I11: =IF(G11="Y",D11,0) -> 0 | J11: Use only if needed to win against another builder.
A12: Bargaining chip | B12: Airbnb for full duration | C12: 0 | D12: =C4*Summary!B9 -> 24942.263 | E12: =C12-D12 -> -24942.263 | F12: =IF((Summary!$B$22+C12)=0,0,(Summary!$B$31+E12)/(Summary!$B$22+C12)) -> -0.03113631 | G12: N | H12: =IF(G12="Y",C12,0) -> 0 | I12: =IF(G12="Y",D12,0) -> 0 | J12: Not recommended — exceeds most of the profit.
A13: Bargaining chip | B13: Price discount | C13: =-C7*Summary!B22 -> -5757.595 | D13: 0 | E13: =C13-D13 -> -5757.595 | F13: =IF((Summary!$B$22+C13)=0,0,(Summary!$B$31+E13)/(Summary!$B$22+C13)) -> 0.036229537 | G13: N | H13: =IF(G13="Y",C13,0) -> 0 | I13: =IF(G13="Y",D13,0) -> 0
A14: Bargaining chip | B14: Beam & posts at cost | C14: =-(Summary!B11-Costs!E46) -> -8300 | D14: 0 | E14: =C14-D14 -> -8300 | F14: =IF((Summary!$B$22+C14)=0,0,(Summary!$B$31+E14)/(Summary!$B$22+C14)) -> 0.02746533 | G14: N | H14: =IF(G14="Y",C14,0) -> 0 | I14: =IF(G14="Y",D14,0) -> 0 | J14: Gives away beam profit.
A15: Bargaining chip | B15: Shower glass included (no charge) | C15: 0 | D15: 2000 | E15: =C15-D15 -> -2000 | F15: =IF((Summary!$B$22+C15)=0,0,(Summary!$B$31+E15)/(Summary!$B$22+C15)) -> 0.048557601 | G15: N | H15: =IF(G15="Y",C15,0) -> 0 | I15: =IF(G15="Y",D15,0) -> 0 | J15: Currently excluded.
A16: Bargaining chip | B16: Lock Option B price if started within 3 months of completion | C16: 0 | D16: 0 | E16: =C16-D16 -> 0 | F16: =IF((Summary!$B$22+C16)=0,0,(Summary!$B$31+E16)/(Summary!$B$22+C16)) -> 0.055504946 | G16: N | H16: =IF(G16="Y",C16,0) -> 0 | I16: =IF(G16="Y",D16,0) -> 0 | J16: No cost now — strong closer.
A17: Bargaining chip | B17: Extended labour warranty (2 → 3 years) | C17: 0 | D17: 1000 | E17: =C17-D17 -> -1000 | F17: =IF((Summary!$B$22+C17)=0,0,(Summary!$B$31+E17)/(Summary!$B$22+C17)) -> 0.052031273 | G17: N | H17: =IF(G17="Y",C17,0) -> 0 | I17: =IF(G17="Y",D17,0) -> 0 | J17: Allowance for callbacks.
A18: Upsell | B18: EV charger rough-in (uses new 200A service) | C18: 1800 | D18: 1000 | E18: =C18-D18 -> 800 | F18: =IF((Summary!$B$22+C18)=0,0,(Summary!$B$31+E18)/(Summary!$B$22+C18)) -> 0.057921722 | G18: N | H18: =IF(G18="Y",C18,0) -> 0 | I18: =IF(G18="Y",D18,0) -> 0 | J18: Estimate.
A19: Upsell | B19: Main-floor pot light pre-wire while wall is open (~10) | C19: 2500 | D19: 1400 | E19: =C19-D19 -> 1100 | F19: =IF((Summary!$B$22+C19)=0,0,(Summary!$B$31+E19)/(Summary!$B$22+C19)) -> 0.058815224 | G19: N | H19: =IF(G19="Y",C19,0) -> 0 | I19: =IF(G19="Y",D19,0) -> 0 | J19: Estimate. Saves cost in Option B later.
A20: Upsell | B20: Stained cedar porch ceiling (vs. standard T&G) | C20: 2200 | D20: 1300 | E20: =C20-D20 -> 900 | F20: =IF((Summary!$B$22+C20)=0,0,(Summary!$B$31+E20)/(Summary!$B$22+C20)) -> 0.058186585 | G20: N | H20: =IF(G20="Y",C20,0) -> 0 | I20: =IF(G20="Y",D20,0) -> 0 | J20: Estimate.
A21: Upsell | B21: Aluminum/steel porch railing (30 LF) vs. PT wood | C21: 6500 | D21: 4200 | E21: =C21-D21 -> 2300 | F21: =IF((Summary!$B$22+C21)=0,0,(Summary!$B$31+E21)/(Summary!$B$22+C21)) -> 0.062092416 | G21: N | H21: =IF(G21="Y",C21,0) -> 0 | I21: =IF(G21="Y",D21,0) -> 0 | J21: Estimate.
A22: Upsell | B22: Cat6 + security camera pre-wire | C22: 1800 | D22: 900 | E22: =C22-D22 -> 900 | F22: =IF((Summary!$B$22+C22)=0,0,(Summary!$B$31+E22)/(Summary!$B$22+C22)) -> 0.058266931 | G22: N | H22: =IF(G22="Y",C22,0) -> 0 | I22: =IF(G22="Y",D22,0) -> 0 | J22: Estimate.
A23: Upsell | B23: Shower glass — PalmView supply & install | C23: 3000 | D23: 2000 | E23: =C23-D23 -> 1000 | F23: =IF((Summary!$B$22+C23)=0,0,(Summary!$B$31+E23)/(Summary!$B$22+C23)) -> 0.05837034 | G23: N | H23: =IF(G23="Y",C23,0) -> 0 | I23: =IF(G23="Y",D23,0) -> 0 | J23: Cost per Raff $2,000.
A24: Upsell | B24: Spray foam at rim joists / band (air-sealing upgrade) | C24: 2500 | D24: 1500 | E24: =C24-D24 -> 1000 | F24: =IF((Summary!$B$22+C24)=0,0,(Summary!$B$31+E24)/(Summary!$B$22+C24)) -> 0.058470847 | G24: N | H24: =IF(G24="Y",C24,0) -> 0 | I24: =IF(G24="Y",D24,0) -> 0 | J24: Estimate.
A25: Cost saving | B25: CA Roofing $3,800 instead of Infinity roofing $6,175 | C25: 0 | D25: -2375 | E25: =C25-D25 -> 2375 | F25: =IF((Summary!$B$22+C25)=0,0,(Summary!$B$31+E25)/(Summary!$B$22+C25)) -> 0.063754919 | G25: N | H25: =IF(G25="Y",C25,0) -> 0 | I25: =IF(G25="Y",D25,0) -> 0 | J25: Both bids approved — confirm scope.
A26: Cost saving | B26: CA Roofing aluminum $3,800 instead of Infinity $8,325 | C26: 0 | D26: -4525 | E26: =C26-D26 -> 4525 | F26: =IF((Summary!$B$22+C26)=0,0,(Summary!$B$31+E26)/(Summary!$B$22+C26)) -> 0.071223315 | G26: N | H26: =IF(G26="Y",C26,0) -> 0 | I26: =IF(G26="Y",D26,0) -> 0 | J26: Both bids approved — confirm scope.
A27: Cost saving | B27: Welda windows $5,221 instead of JS $5,545 | C27: 0 | D27: -324 | E27: =C27-D27 -> 324 | F27: =IF((Summary!$B$22+C27)=0,0,(Summary!$B$31+E27)/(Summary!$B$22+C27)) -> 0.056630416 | G27: N | H27: =IF(G27="Y",C27,0) -> 0 | I27: =IF(G27="Y",D27,0) -> 0
A28: Cost saving | B28: No basement footings needed under beam | C28: 0 | D28: -3000 | E28: =C28-D28 -> 3000 | F28: =IF((Summary!$B$22+C28)=0,0,(Summary!$B$31+E28)/(Summary!$B$22+C28)) -> 0.065925964 | G28: N | H28: =IF(G28="Y",C28,0) -> 0 | I28: =IF(G28="Y",D28,0) -> 0 | J28: Pending engineer.
B29: TOTAL OF SELECTED ITEMS | E29: =H29-I29 -> -7500 | H29: =SUM(H10:H28) -> 0 | I29: =SUM(I10:I28) -> 7500
B30: Adjusted margin (see Summary) | E30: =Summary!B43 -> 0.029452402

Sheet Schedule
A1: Schedule & Start Date
A2: Phase weeks in blue drive the duration, PM, site labour and overhead. Phases shown sequentially; exterior and interior work can overlap to shorten the job.
A4: # | B4: Construction phase | C4: Weeks | D4: Start | E4: Finish | F4: Notes
A5: 1 | B5: Mobilization; demo roof, 2nd floor, chimney; porch demo | C5: 2 | D5: =Summary!B6 -> 46524 | E5: =D5+C5*7-3 -> 46535 | F5: Clients moved out before this date.
A6: 2 | B6: Porch piers; main-floor shoring, beam & posts; basement point loads | C6: 2 | D6: =E5+3 -> 46538 | E6: =D6+C6*7-3 -> 46549 | F6: Engineer review.
A7: 3 | B7: Second-floor framing, roof structure, sheathing & dry-in | C7: 5 | D7: =E6+3 -> 46552 | E7: =D7+C7*7-3 -> 46584
A8: 4 | B8: Roofing, windows, house wrap | C8: 2 | D8: =E7+3 -> 46587 | E8: =D8+C8*7-3 -> 46598
A9: 5 | B9: Rough-ins: plumbing, HVAC, electrical, 200A service + inspections | C9: 3 | D9: =E8+3 -> 46601 | E9: =D9+C9*7-3 -> 46619 | F9: Toronto Hydro disconnect/reconnect.
A10: 6 | B10: Insulation & drywall (Level 4) | C10: 3 | D10: =E9+3 -> 46622 | E10: =D10+C10*7-3 -> 46640 | F10: Insulation inspection.
A11: 7 | B11: Bathroom tile, flooring, stairs, trim & paint | C11: 4 | D11: =E10+3 -> 46643 | E11: =D11+C11*7-3 -> 46668 | F11: Client finish selections must be on site.
A12: 8 | B12: Siding, Maibec, aluminum, porch finishing | C12: 2 | D12: =E11+3 -> 46671 | E12: =D12+C12*7-3 -> 46682 | F12: Can overlap interior phases.
A13: 9 | B13: Final fixtures, deficiencies, final inspections, clean | C13: 1 | D13: =E12+3 -> 46685 | E13: =D13+C13*7-3 -> 46689
B16: TOTAL DURATION (weeks) | C16: =SUM(C5:C13) -> 24 | D16: =D5 -> 46524 | E16: =E13 -> 46689
A19: PRE-CONSTRUCTION TARGETS (estimates — confirm with Mark and the City)
A20: # | B20: Milestone | D20: Target date | F20: Notes
A21: 1 | B21: Site visit with Julianne & David | D21: 46311 | F21: Today 4–5pm.
A22: 2 | B22: Engineer confirms beam/post load path | D22: 46339
A23: 3 | B23: Mark revises drawings (2nd floor, porch, beam only) | D23: 46353
A24: 4 | B24: Permit submission to City of Toronto | D24: 46360
A25: 5 | B25: Revised estimate signed + deposit | D25: 46402 | F25: Locks the May start.
A26: 6 | B26: Permit issued (est.) | D26: 46477 | F26: Toronto residential additions often take 2–4 months.
A27: 7 | B27: Client finish selections complete | D27: 46492
A28: 8 | B28: Clients move out | D28: =Summary!B6-2 -> 46522 | F28: Weekend before start.
A29: 9 | B29: Construction start | D29: =Summary!B6 -> 46524
A30: 10 | B30: Substantial completion | D30: =E16 -> 46689

Sheet Duration vs Margin
A1: Duration vs. Margin — what each week costs
A2: Base case, no offers. Uses Summary rates and costs; FV price varies across columns. Contract price fixed at Summary B22.
A4: FV price → | B4: 35000 | C4: 37500 | D4: 40000 | F4: =B4 -> 35000 | G4: =C4 -> 37500 | H4: =D4 -> 40000
A5: Weeks | B5: Margin | C5: Margin | D5: Margin | F5: Net profit | G5: Net profit | H5: Net profit
A6: 12 | B6: =IF(Summary!$B$22=0,0,F6/Summary!$B$22) -> 0.20174656 | C6: =IF(Summary!$B$22=0,0,G6/Summary!$B$22) -> 0.19306238 | D6: =IF(Summary!$B$22=0,0,H6/Summary!$B$22) -> 0.1843782 | F6: =Summary!$B$22-(Costs!$E$36-Summary!$B$13+B$4+Costs!$E$46+$A6*Summary!$B$34) -> 58078.75 | G6: =Summary!$B$22-(Costs!$E$36-Summary!$B$13+C$4+Costs!$E$46+$A6*Summary!$B$34) -> 55578.75 | H6: =Summary!$B$22-(Costs!$E$36-Summary!$B$13+D$4+Costs!$E$46+$A6*Summary!$B$34) -> 53078.75
A7: 16 | B7: =IF(Summary!$B$22=0,0,F7/Summary!$B$22) -> 0.15589408 | C7: =IF(Summary!$B$22=0,0,G7/Summary!$B$22) -> 0.1472099 | D7: =IF(Summary!$B$22=0,0,H7/Summary!$B$22) -> 0.13852572 | F7: =Summary!$B$22-(Costs!$E$36-Summary!$B$13+B$4+Costs!$E$46+$A7*Summary!$B$34) -> 44878.75 | G7: =Summary!$B$22-(Costs!$E$36-Summary!$B$13+C$4+Costs!$E$46+$A7*Summary!$B$34) -> 42378.75 | H7: =Summary!$B$22-(Costs!$E$36-Summary!$B$13+D$4+Costs!$E$46+$A7*Summary!$B$34) -> 39878.75
A8: 20 | B8: =IF(Summary!$B$22=0,0,F8/Summary!$B$22) -> 0.11004161 | C8: =IF(Summary!$B$22=0,0,G8/Summary!$B$22) -> 0.10135742 | D8: =IF(Summary!$B$22=0,0,H8/Summary!$B$22) -> 0.092673243 | F8: =Summary!$B$22-(Costs!$E$36-Summary!$B$13+B$4+Costs!$E$46+$A8*Summary!$B$34) -> 31678.75 | G8: =Summary!$B$22-(Costs!$E$36-Summary!$B$13+C$4+Costs!$E$46+$A8*Summary!$B$34) -> 29178.75 | H8: =Summary!$B$22-(Costs!$E$36-Summary!$B$13+D$4+Costs!$E$46+$A8*Summary!$B$34) -> 26678.75
A9: 24 | B9: =IF(Summary!$B$22=0,0,F9/Summary!$B$22) -> 0.064189128 | C9: =IF(Summary!$B$22=0,0,G9/Summary!$B$22) -> 0.055504946 | D9: =IF(Summary!$B$22=0,0,H9/Summary!$B$22) -> 0.046820765 | F9: =Summary!$B$22-(Costs!$E$36-Summary!$B$13+B$4+Costs!$E$46+$A9*Summary!$B$34) -> 18478.75 | G9: =Summary!$B$22-(Costs!$E$36-Summary!$B$13+C$4+Costs!$E$46+$A9*Summary!$B$34) -> 15978.75 | H9: =Summary!$B$22-(Costs!$E$36-Summary!$B$13+D$4+Costs!$E$46+$A9*Summary!$B$34) -> 13478.75
A10: 28 | B10: =IF(Summary!$B$22=0,0,F10/Summary!$B$22) -> 0.018336649 | C10: =IF(Summary!$B$22=0,0,G10/Summary!$B$22) -> 0.0096524677 | D10: =IF(Summary!$B$22=0,0,H10/Summary!$B$22) -> 0.00096828624 | F10: =Summary!$B$22-(Costs!$E$36-Summary!$B$13+B$4+Costs!$E$46+$A10*Summary!$B$34) -> 5278.75 | G10: =Summary!$B$22-(Costs!$E$36-Summary!$B$13+C$4+Costs!$E$46+$A10*Summary!$B$34) -> 2778.75 | H10: =Summary!$B$22-(Costs!$E$36-Summary!$B$13+D$4+Costs!$E$46+$A10*Summary!$B$34) -> 278.75
A11: 32 | B11: =IF(Summary!$B$22=0,0,F11/Summary!$B$22) -> -0.027515829 | C11: =IF(Summary!$B$22=0,0,G11/Summary!$B$22) -> -0.036200011 | D11: =IF(Summary!$B$22=0,0,H11/Summary!$B$22) -> -0.044884192 | F11: =Summary!$B$22-(Costs!$E$36-Summary!$B$13+B$4+Costs!$E$46+$A11*Summary!$B$34) -> -7921.25 | G11: =Summary!$B$22-(Costs!$E$36-Summary!$B$13+C$4+Costs!$E$46+$A11*Summary!$B$34) -> -10421.25 | H11: =Summary!$B$22-(Costs!$E$36-Summary!$B$13+D$4+Costs!$E$46+$A11*Summary!$B$34) -> -12921.25
A13: Red = under 10% margin · Green = 20%+ margin
